Workbook

Sheet Dashboard
A1: DASHBOARD
A3: Estado | B3: Plantilla V4 lista | D3: Indicadores (se llenarán automáticamente)
D4: Líder | E4: =IF('Tabla Posiciones'!B2="","-",'Tabla Posiciones'!B2) -> Pachuca
A5: Partidos | B5: ✓ | D5: Top Goleador | E5: =IF(Goleadores!$B$2="","-",IF(COUNTIF(Goleadores!$D$2:$D$1501,Goleadores!$D$2)=1,Goleadores!$B$2,IF(COUNTIF(Goleadores!$D$2:$D$1501,Goleadores!$D$2)=2,Goleadores!$B$2&" / "&Goleadores!$B$3,IF(COUNTIF(Goleadores!$D$2:$D$1501,Goleadores!$D$2)=3,Goleadores!$B$2&" / "&Goleadores!$B$3&" / "&Goleadores!$B$4,Goleadores!$B$2&" / "&Goleadores!$B$3&" / "&Goleadores!$B$4&" +"&(COUNTIF(Goleadores!$D$2:$D$1501,Goleadores!$D$2)-3)&" más")))) -> Rondón Salomon / El Ghezouani Mourad / Ocampos Lucas +1 más
A6: Tabla de Posiciones | B6: ✓ | D6: Top Asistente | E6: =IF(Asistencias!$B$2="","-",IF(COUNTIF(Asistencias!$D$2:$D$1501,Asistencias!$D$2)=1,Asistencias!$B$2,IF(COUNTIF(Asistencias!$D$2:$D$1501,Asistencias!$D$2)=2,Asistencias!$B$2&" / "&Asistencias!$B$3,IF(COUNTIF(Asistencias!$D$2:$D$1501,Asistencias!$D$2)=3,Asistencias!$B$2&" / "&Asistencias!$B$3&" / "&Asistencias!$B$4,Asistencias!$B$2&" / "&Asistencias!$B$3&" / "&Asistencias!$B$4&" +"&(COUNTIF(Asistencias!$D$2:$D$1501,Asistencias!$D$2)-3)&" más")))) -> Montiel Elias / Idrissi Oussama / Padilla Nanitamo +14 más
A7: Jugadores | B7: ✓ | D7: Top Remates al Arco | E7: =IF('Remates al Arco'!$B$2="","-",IF(COUNTIF('Remates al Arco'!$D$2:$D$1501,'Remates al Arco'!$D$2)=1,'Remates al Arco'!$B$2,IF(COUNTIF('Remates al Arco'!$D$2:$D$1501,'Remates al Arco'!$D$2)=2,'Remates al Arco'!$B$2&" / "&'Remates al Arco'!$B$3,IF(COUNTIF('Remates al Arco'!$D$2:$D$1501,'Remates al Arco'!$D$2)=3,'Remates al Arco'!$B$2&" / "&'Remates al Arco'!$B$3&" / "&'Remates al Arco'!$B$4,'Remates al Arco'!$B$2&" / "&'Remates al Arco'!$B$3&" / "&'Remates al Arco'!$B$4&" +"&(COUNTIF('Remates al Arco'!$D$2:$D$1501,'Remates al Arco'!$D$2)-3)&" más")))) -> Orellano Luca
A8: Estadísticas Jugadores | B8: ✓ | D8: Equipo más goleador | E8: =IF('Tabla Posiciones'!$B$2="","-",IF(COUNTIF('Tabla Posiciones'!$AO$2:$AO$61,1)=1,IFERROR(INDEX('Tabla Posiciones'!$N$2:$N$61,MATCH("GF|1",'Tabla Posiciones'!$AQ$2:$AQ$61,0)),""),IF(COUNTIF('Tabla Posiciones'!$AO$2:$AO$61,1)=2,IFERROR(INDEX('Tabla Posiciones'!$N$2:$N$61,MATCH("GF|1",'Tabla Posiciones'!$AQ$2:$AQ$61,0)),"")&" / "&IFERROR(INDEX('Tabla Posiciones'!$N$2:$N$61,MATCH("GF|2",'Tabla Posiciones'!$AQ$2:$AQ$61,0)),""),IF(COUNTIF('Tabla Posiciones'!$AO$2:$AO$61,1)=3,IFERROR(INDEX('Tabla Posiciones'!$N$2:$N$61,MATCH("GF|1",'Tabla Posiciones'!$AQ$2:$AQ$61,0)),"")&" / "&IFERROR(INDEX('Tabla Posiciones'!$N$2:$N$61,MATCH("GF|2",'Tabla Posiciones'!$AQ$2:$AQ$61,0)),"")&" / "&IFERROR(INDEX('Tabla Posiciones'!$N$2:$N$61,MATCH("GF|3",'Tabla Posiciones'!$AQ$2:$AQ$61,0)),""),IFERROR(INDEX('Tabla Posiciones'!$N$2:$N$61,MATCH("GF|1",'Tabla Posiciones'!$AQ$2:$AQ$61,0)),"")&" / "&IFERROR(INDEX('Tabla Posiciones'!$N$2:$N$61,MATCH("GF|2",'Tabla Posiciones'!$AQ$2:$AQ$61,0)),"")&" / "&IFERROR(INDEX('Tabla Posiciones'!$N$2:$N$61,MATCH("GF|3",'Tabla Posiciones'!$AQ$2:$AQ$61,0)),"")&" +"&(COUNTIF('Tabla Posiciones'!$AO$2:$AO$61,1)-3)&" más")))) -> Tijuana / Atlas / Cruz Azul +2 más
A9: Goleadores | B9: ✓ | D9: Equipo mejor defensa | E9: =IF('Tabla Posiciones'!$B$2="","-",IF(COUNTIF('Tabla Posiciones'!$AR$2:$AR$61,1)=1,IFERROR(INDEX('Tabla Posiciones'!$N$2:$N$61,MATCH("GC|1",'Tabla Posiciones'!$AT$2:$AT$61,0)),""),IF(COUNTIF('Tabla Posiciones'!$AR$2:$AR$61,1)=2,IFERROR(INDEX('Tabla Posiciones'!$N$2:$N$61,MATCH("GC|1",'Tabla Posiciones'!$AT$2:$AT$61,0)),"")&" / "&IFERROR(INDEX('Tabla Posiciones'!$N$2:$N$61,MATCH("GC|2",'Tabla Posiciones'!$AT$2:$AT$61,0)),""),IF(COUNTIF('Tabla Posiciones'!$AR$2:$AR$61,1)=3,IFERROR(INDEX('Tabla Posiciones'!$N$2:$N$61,MATCH("GC|1",'Tabla Posiciones'!$AT$2:$AT$61,0)),"")&" / "&IFERROR(INDEX('Tabla Posiciones'!$N$2:$N$61,MATCH("GC|2",'Tabla Posiciones'!$AT$2:$AT$61,0)),"")&" / "&IFERROR(INDEX('Tabla Posiciones'!$N$2:$N$61,MATCH("GC|3",'Tabla Posiciones'!$AT$2:$AT$61,0)),""),IFERROR(INDEX('Tabla Posiciones'!$N$2:$N$61,MATCH("GC|1",'Tabla Posiciones'!$AT$2:$AT$61,0)),"")&" / "&IFERROR(INDEX('Tabla Posiciones'!$N$2:$N$61,MATCH("GC|2",'Tabla Posiciones'!$AT$2:$AT$61,0)),"")&" / "&IFERROR(INDEX('Tabla Posiciones'!$N$2:$N$61,MATCH("GC|3",'Tabla Posiciones'!$AT$2:$AT$61,0)),"")&" +"&(COUNTIF('Tabla Posiciones'!$AR$2:$AR$61,1)-3)&" más")))) -> Puebla / Pachuca / Toluca +1 más
A10: Asistencias | B10: ✓
A11: Remates al Arco | B11: ✓

Sheet Partidos
A1: Fecha | B1: Jornada | C1: Local | D1: Visitante | E1: Goles L | F1: Goles V | G1: Goles HT L | H1: Goles HT V | I1: xG L | J1: xG V | K1: Remates L | L1: Remates V | M1: Remates Arco L | N1: Remates Arco V | O1: Posesión L | P1: Posesión V | Q1: Corners L | R1: Corners V | S1: Portero L | T1: Atajadas L | U1: Portero V | V1: Atajadas V | W1: Aux: N° partido Local | X1: Aux: N° partido Visit | Y1: Aux: Clave Local | Z1: Aux: Clave Visit | AA1: Aux: nuevo Local? | AB1: Aux: nuevo Visit? | AC1: Aux: seq Local | AD1: Aux: seq Visit | AE1: Aux: clave equipo Local | AF1: Aux: clave equipo Visit | AG1: Rojas Local | AH1: Expulsados Local (jugador y minuto) | AI1: Rojas Visita | AJ1: Expulsados Visita (jugador y minuto)
A2: 46219 | B2: 1 | C2: Necaxa | D2: Atlante | E2: 2 | F2: 1 | G2: 0 | H2: 0 | I2: 2.39 | J2: 0.6 | K2: 11 | L2: 12 | M2: 5 | N2: 3 | O2: 0.64 | P2: 0.36 | Q2: 11 | R2: 5 | S2: Jimenez Luis | T2: 2 | U2: Jimenez Oscar | V2: 3 | W2: =IF($C2="","",SUMPRODUCT(($C$2:C2=C2)+($D$2:D2=C2))) -> 1 | X2: =IF($D2="","",SUMPRODUCT(($C$2:C2=D2)+($D$2:D2=D2))) -> 1 | Y2: =IF($C2="","",C2&"|"&W2) -> Necaxa|1 | Z2: =IF($D2="","",D2&"|"&X2) -> Atlante|1 | AA2: =IF($C2="","",IF(COUNTIF($C$1:C1,$C2)+COUNTIF($D$1:D1,$C2)=0,1,0)) -> 1 | AB2: =IF($D2="","",IF(COUNTIF($C$1:C2,$D2)+COUNTIF($D$1:D1,$D2)=0,1,0)) -> 1 | AC2: =IF(AA2=1,SUM($AA$2:AA2)-AA2+SUM($AB$2:AB2)-AB2+1,"") -> 1 | AD2: =IF(AB2=1,SUM($AA$2:AA2)+SUM($AB$2:AB2)-AB2+1,"") -> 2 | AE2: =IF(AC2="","","TEAM|"&AC2) -> TEAM|1 | AF2: =IF(AD2="","","TEAM|"&AD2) -> TEAM|2 | AG2: =IF(AH2="",0,LEN(AH2)-LEN(SUBSTITUTE(AH2,"/",""))+1) -> 0 | AI2: =IF(AJ2="",0,LEN(AJ2)-LEN(SUBSTITUTE(AJ2,"/",""))+1) -> 0
A3: 46219 | B3: 1 | C3: Tijuana | D3: Tigres UANL | E3: 3 | F3: 1 | G3: 1 | H3: 0 | I3: 2.01 | J3: 0.61 | K3: 14 | L3: 8 | M3: 7 | N3: 4 | O3: 0.51 | P3: 0.49 | Q3: 1 | R3: 4 | S3: Rodríguez Antonio | T3: 3 | U3: Guzman Nahuel | V3: 4 | W3: =IF($C3="","",SUMPRODUCT(($C$2:C3=C3)+($D$2:D3=C3))) -> 1 | X3: =IF($D3="","",SUMPRODUCT(($C$2:C3=D3)+($D$2:D3=D3))) -> 1 | Y3: =IF($C3="","",C3&"|"&W3) -> Tijuana|1 | Z3: =IF($D3="","",D3&"|"&X3) -> Tigres UANL|1 | AA3: =IF($C3="","",IF(COUNTIF($C$1:C2,$C3)+COUNTIF($D$1:D2,$C3)=0,1,0)) -> 1 | AB3: =IF($D3="","",IF(COUNTIF($C$1:C3,$D3)+COUNTIF($D$1:D2,$D3)=0,1,0)) -> 1 | AC3: =IF(AA3=1,SUM($AA$2:AA3)-AA3+SUM($AB$2:AB3)-AB3+1,"") -> 3 | AD3: =IF(AB3=1,SUM($AA$2:AA3)+SUM($AB$2:AB3)-AB3+1,"") -> 4 | AE3: =IF(AC3="","","TEAM|"&AC3) -> TEAM|3 | AF3: =IF(AD3="","","TEAM|"&AD3) -> TEAM|4 | AG3: =IF(AH3="",0,LEN(AH3)-LEN(SUBSTITUTE(AH3,"/",""))+1) -> 0 | AI3: =IF(AJ3="",0,LEN(AJ3)-LEN(SUBSTITUTE(AJ3,"/",""))+1) -> 1 | AJ3: Aguirre Rodrigo (45+1')
A4: 46220 | B4: 1 | C4: León | D4: Atlas | E4: 2 | F4: 3 | G4: 1 | H4: 1 | I4: 1.36 | J4: 1.75 | K4: 16 | L4: 9 | M4: 8 | N4: 7 | O4: 0.46 | P4: 0.54 | Q4: 6 | R4: 2 | S4: Garcia Oscar | T4: 4 | U4: Sanchez Antonio | V4: 6 | W4: =IF($C4="","",SUMPRODUCT(($C$2:C4=C4)+($D$2:D4=C4))) -> 1 | X4: =IF($D4="","",SUMPRODUCT(($C$2:C4=D4)+($D$2:D4=D4))) -> 1 | Y4: =IF($C4="","",C4&"|"&W4) -> León|1 | Z4: =IF($D4="","",D4&"|"&X4) -> Atlas|1 | AA4: =IF($C4="","",IF(COUNTIF($C$1:C3,$C4)+COUNTIF($D$1:D3,$C4)=0,1,0)) -> 1 | AB4: =IF($D4="","",IF(COUNTIF($C$1:C4,$D4)+COUNTIF($D$1:D3,$D4)=0,1,0)) -> 1 | AC4: =IF(AA4=1,SUM($AA$2:AA4)-AA4+SUM($AB$2:AB4)-AB4+1,"") -> 5 | AD4: =IF(AB4=1,SUM($AA$2:AA4)+SUM($AB$2:AB4)-AB4+1,"") -> 6 | AE4: =IF(AC4="","","TEAM|"&AC4) -> TEAM|5 | AF4: =IF(AD4="","","TEAM|"&AD4) -> TEAM|6 | AG4: =IF(AH4="",0,LEN(AH4)-LEN(SUBSTITUTE(AH4,"/",""))+1) -> 1 | AH4: Cambindo Abonia Diber Armando (42') | AI4: =IF(AJ4="",0,LEN(AJ4)-LEN(SUBSTITUTE(AJ4,"/",""))+1) -> 0
A5: 46220 | B5: 1 | C5: Atlético de San Luis | D5: Cruz Azul | E5: 2 | F5: 3 | G5: 0 | H5: 0 | I5: 1.29 | J5: 3.14 | K5: 13 | L5: 20 | M5: 5 | N5: 10 | O5: 0.46 | P5: 0.54 | Q5: 4 | R5: 4 | S5: Sanchez Andres | T5: 6 | U5: Mier Kevin | V5: 4 | W5: =IF($C5="","",SUMPRODUCT(($C$2:C5=C5)+($D$2:D5=C5))) -> 1 | X5: =IF($D5="","",SUMPRODUCT(($C$2:C5=D5)+($D$2:D5=D5))) -> 1 | Y5: =IF($C5="","",C5&"|"&W5) -> Atlético de San Luis|1 | Z5: =IF($D5="","",D5&"|"&X5) -> Cruz Azul|1 | AA5: =IF($C5="","",IF(COUNTIF($C$1:C4,$C5)+COUNTIF($D$1:D4,$C5)=0,1,0)) -> 1 | AB5: =IF($D5="","",IF(COUNTIF($C$1:C5,$D5)+COUNTIF($D$1:D4,$D5)=0,1,0)) -> 1 | AC5: =IF(AA5=1,SUM($AA$2:AA5)-AA5+SUM($AB$2:AB5)-AB5+1,"") -> 7 | AD5: =IF(AB5=1,SUM($AA$2:AA5)+SUM($AB$2:AB5)-AB5+1,"") -> 8 | AE5: =IF(AC5="","","TEAM|"&AC5) -> TEAM|7 | AF5: =IF(AD5="","","TEAM|"&AD5) -> TEAM|8 | AG5: =IF(AH5="",0,LEN(AH5)-LEN(SUBSTITUTE(AH5,"/",""))+1) -> 0 | AI5: =IF(AJ5="",0,LEN(AJ5)-LEN(SUBSTITUTE(AJ5,"/",""))+1) -> 0
A6: 46220 | B6: 1 | C6: Juárez | D6: Puebla | E6: 0 | F6: 1 | G6: 0 | H6: 1 | I6: 0.86 | J6: 1.21 | K6: 13 | L6: 13 | M6: 1 | N6: 5 | O6: 0.65 | P6: 0.35 | Q6: 5 | R6: 7 | S6: Jurado Sebastian | T6: 4 | U6: Gutierrez Daniel | V6: 1 | W6: =IF($C6="","",SUMPRODUCT(($C$2:C6=C6)+($D$2:D6=C6))) -> 1 | X6: =IF($D6="","",SUMPRODUCT(($C$2:C6=D6)+($D$2:D6=D6))) -> 1 | Y6: =IF($C6="","",C6&"|"&W6) -> Juárez|1 | Z6: =IF($D6="","",D6&"|"&X6) -> Puebla|1 | AA6: =IF($C6="","",IF(COUNTIF($C$1:C5,$C6)+COUNTIF($D$1:D5,$C6)=0,1,0)) -> 1 | AB6: =IF($D6="","",IF(COUNTIF($C$1:C6,$D6)+COUNTIF($D$1:D5,$D6)=0,1,0)) -> 1 | AC6: =IF(AA6=1,SUM($AA$2:AA6)-AA6+SUM($AB$2:AB6)-AB6+1,"") -> 9 | AD6: =IF(AB6=1,SUM($AA$2:AA6)+SUM($AB$2:AB6)-AB6+1,"") -> 10 | AE6: =IF(AC6="","","TEAM|"&AC6) -> TEAM|9 | AF6: =IF(AD6="","","TEAM|"&AD6) -> TEAM|10 | AG6: =IF(AH6="",0,LEN(AH6)-LEN(SUBSTITUTE(AH6,"/",""))+1) -> 0 | AI6: =IF(AJ6="",0,LEN(AJ6)-LEN(SUBSTITUTE(AJ6,"/",""))+1) -> 1 | AJ6: Moreno Iker (64')
A7: 46221 | B7: 1 | C7: Pumas UNAM | D7: Pachuca | E7: 0 | F7: 3 | G7: 0 | H7: 2 | I7: 0.28 | J7: 1.08 | K7: 9 | L7: 15 | M7: 1 | N7: 6 | O7: 0.61 | P7: 0.39 | Q7: 9 | R7: 4 | S7: Navas Keylor | T7: 3 | U7: Moreno Carlos | V7: 1 | W7: =IF($C7="","",SUMPRODUCT(($C$2:C7=C7)+($D$2:D7=C7))) -> 1 | X7: =IF($D7="","",SUMPRODUCT(($C$2:C7=D7)+($D$2:D7=D7))) -> 1 | Y7: =IF($C7="","",C7&"|"&W7) -> Pumas UNAM|1 | Z7: =IF($D7="","",D7&"|"&X7) -> Pachuca|1 | AA7: =IF($C7="","",IF(COUNTIF($C$1:C6,$C7)+COUNTIF($D$1:D6,$C7)=0,1,0)) -> 1 | AB7: =IF($D7="","",IF(COUNTIF($C$1:C7,$D7)+COUNTIF($D$1:D6,$D7)=0,1,0)) -> 1 | AC7: =IF(AA7=1,SUM($AA$2:AA7)-AA7+SUM($AB$2:AB7)-AB7+1,"") -> 11 | AD7: =IF(AB7=1,SUM($AA$2:AA7)+SUM($AB$2:AB7)-AB7+1,"") -> 12 | AE7: =IF(AC7="","","TEAM|"&AC7) -> TEAM|11 | AF7: =IF(AD7="","","TEAM|"&AD7) -> TEAM|12 | AG7: =IF(AH7="",0,LEN(AH7)-LEN(SUBSTITUTE(AH7,"/",""))+1) -> 0 | AI7: =IF(AJ7="",0,LEN(AJ7)-LEN(SUBSTITUTE(AJ7,"/",""))+1) -> 0
A8: 46221 | B8: 1 | C8: Monterrey | D8: Santos Laguna | E8: 3 | F8: 2 | G8: 3 | H8: 1 | I8: 1.82 | J8: 2.05 | K8: 19 | L8: 11 | M8: 13 | N8: 3 | O8: 0.57 | P8: 0.43 | Q8: 5 | R8: 5 | S8: Cardenas Luis | T8: 1 | U8: Acevedo Carlos | V8: 10 | W8: =IF($C8="","",SUMPRODUCT(($C$2:C8=C8)+($D$2:D8=C8))) -> 1 | X8: =IF($D8="","",SUMPRODUCT(($C$2:C8=D8)+($D$2:D8=D8))) -> 1 | Y8: =IF($C8="","",C8&"|"&W8) -> Monterrey|1 | Z8: =IF($D8="","",D8&"|"&X8) -> Santos Laguna|1 | AA8: =IF($C8="","",IF(COUNTIF($C$1:C7,$C8)+COUNTIF($D$1:D7,$C8)=0,1,0)) -> 1 | AB8: =IF($D8="","",IF(COUNTIF($C$1:C8,$D8)+COUNTIF($D$1:D7,$D8)=0,1,0)) -> 1 | AC8: =IF(AA8=1,SUM($AA$2:AA8)-AA8+SUM($AB$2:AB8)-AB8+1,"") -> 13 | AD8: =IF(AB8=1,SUM($AA$2:AA8)+SUM($AB$2:AB8)-AB8+1,"") -> 14 | AE8: =IF(AC8="","","TEAM|"&AC8) -> TEAM|13 | AF8: =IF(AD8="","","TEAM|"&AD8) -> TEAM|14 | AG8: =IF(AH8="",0,LEN(AH8)-LEN(SUBSTITUTE(AH8,"/",""))+1) -> 0 | AI8: =IF(AJ8="",0,LEN(AJ8)-LEN(SUBSTITUTE(AJ8,"/",""))+1) -> 0
A9: 46221 | B9: 1 | C9: Guadalajara | D9: Toluca | E9: 0 | F9: 2 | G9: 0 | H9: 1 | I9: 1.09 | J9: 1.77 | K9: 13 | L9: 14 | M9: 4 | N9: 9 | O9: 0.4 | P9: 0.6 | Q9: 9 | R9: 2 | S9: Rangel Raul | T9: 7 | U9: Garcia Palomera Luis Manuel | V9: 4 | W9: =IF($C9="","",SUMPRODUCT(($C$2:C9=C9)+($D$2:D9=C9))) -> 1 | X9: =IF($D9="","",SUMPRODUCT(($C$2:C9=D9)+($D$2:D9=D9))) -> 1 | Y9: =IF($C9="","",C9&"|"&W9) -> Guadalajara|1 | Z9: =IF($D9="","",D9&"|"&X9) -> Toluca|1 | AA9: =IF($C9="","",IF(COUNTIF($C$1:C8,$C9)+COUNTIF($D$1:D8,$C9)=0,1,0)) -> 1 | AB9: =IF($D9="","",IF(COUNTIF($C$1:C9,$D9)+COUNTIF($D$1:D8,$D9)=0,1,0)) -> 1 | AC9: =IF(AA9=1,SUM($AA$2:AA9)-AA9+SUM($AB$2:AB9)-AB9+1,"") -> 15 | AD9: =IF(AB9=1,SUM($AA$2:AA9)+SUM($AB$2:AB9)-AB9+1,"") -> 16 | AE9: =IF(AC9="","","TEAM|"&AC9) -> TEAM|15 | AF9: =IF(AD9="","","TEAM|"&AD9) -> TEAM|16 | AG9: =IF(AH9="",0,LEN(AH9)-LEN(SUBSTITUTE(AH9,"/",""))+1) -> 1 | AH9: Sepúlveda Ángel Baltazar (50') | AI9: =IF(AJ9="",0,LEN(AJ9)-LEN(SUBSTITUTE(AJ9,"/",""))+1) -> 0
A10: 46221 | B10: 1 | C10: Querétaro | D10: Club América | E10: 0 | F10: 1 | G10: 0 | H10: 0 | I10: 0.95 | J10: 1.64 | K10: 10 | L10: 17 | M10: 2 | N10: 5 | O10: 0.38 | P10: 0.62 | Q10: 2 | R10: 12 | S10: Allison Revuelta Guillermo | T10: 4 | U10: Cota Rodolfo | V10: 2 | W10: =IF($C10="","",SUMPRODUCT(($C$2:C10=C10)+($D$2:D10=C10))) -> 1 | X10: =IF($D10="","",SUMPRODUCT(($C$2:C10=D10)+($D$2:D10=D10))) -> 1 | Y10: =IF($C10="","",C10&"|"&W10) -> Querétaro|1 | Z10: =IF($D10="","",D10&"|"&X10) -> Club América|1 | AA10: =IF($C10="","",IF(COUNTIF($C$1:C9,$C10)+COUNTIF($D$1:D9,$C10)=0,1,0)) -> 1 | AB10: =IF($D10="","",IF(COUNTIF($C$1:C10,$D10)+COUNTIF($D$1:D9,$D10)=0,1,0)) -> 1 | AC10: =IF(AA10=1,SUM($AA$2:AA10)-AA10+SUM($AB$2:AB10)-AB10+1,"") -> 17 | AD10: =IF(AB10=1,SUM($AA$2:AA10)+SUM($AB$2:AB10)-AB10+1,"") -> 18 | AE10: =IF(AC10="","","TEAM|"&AC10) -> TEAM|17 | AF10: =IF(AD10="","","TEAM|"&AD10) -> TEAM|18 | AG10: =IF(AH10="",0,LEN(AH10)-LEN(SUBSTITUTE(AH10,"/",""))+1) -> 0 | AI10: =IF(AJ10="",0,LEN(AJ10)-LEN(SUBSTITUTE(AJ10,"/",""))+1) -> 1 | AJ10: Cervantes Martin del Campo Alan Jhosue (88')
W11: =IF($C11="","",SUMPRODUCT(($C$2:C11=C11)+($D$2:D11=C11))) | X11: =IF($D11="","",SUMPRODUCT(($C$2:C11=D11)+($D$2:D11=D11))) | Y11: =IF($C11="","",C11&"|"&W11) | Z11: =IF($D11="","",D11&"|"&X11) | AA11: =IF($C11="","",IF(COUNTIF($C$1:C10,$C11)+COUNTIF($D$1:D10,$C11)=0,1,0)) | AB11: =IF($D11="","",IF(COUNTIF($C$1:C11,$D11)+COUNTIF($D$1:D10,$D11)=0,1,0)) | AC11: =IF(AA11=1,SUM($AA$2:AA11)-AA11+SUM($AB$2:AB11)-AB11+1,"") | AD11: =IF(AB11=1,SUM($AA$2:AA11)+SUM($AB$2:AB11)-AB11+1,"") | AE11: =IF(AC11="","","TEAM|"&AC11) | AF11: =IF(AD11="","","TEAM|"&AD11) | AG11: =IF(AH11="",0,LEN(AH11)-LEN(SUBSTITUTE(AH11,"/",""))+1) -> 0 | AI11: =IF(AJ11="",0,LEN(AJ11)-LEN(SUBSTITUTE(AJ11,"/",""))+1) -> 0
W12: =IF($C12="","",SUMPRODUCT(($C$2:C12=C12)+($D$2:D12=C12))) | X12: =IF($D12="","",SUMPRODUCT(($C$2:C12=D12)+($D$2:D12=D12))) | Y12: =IF($C12="","",C12&"|"&W12) | Z12: =IF($D12="","",D12&"|"&X12) | AA12: =IF($C12="","",IF(COUNTIF($C$1:C11,$C12)+COUNTIF($D$1:D11,$C12)=0,1,0)) | AB12: =IF($D12="","",IF(COUNTIF($C$1:C12,$D12)+COUNTIF($D$1:D11,$D12)=0,1,0)) | AC12: =IF(AA12=1,SUM($AA$2:AA12)-AA12+SUM($AB$2:AB12)-AB12+1,"") | AD12: =IF(AB12=1,SUM($AA$2:AA12)+SUM($AB$2:AB12)-AB12+1,"") | AE12: =IF(AC12="","","TEAM|"&AC12) | AF12: =IF(AD12="","","TEAM|"&AD12) | AG12: =IF(AH12="",0,LEN(AH12)-LEN(SUBSTITUTE(AH12,"/",""))+1) -> 0 | AI12: =IF(AJ12="",0,LEN(AJ12)-LEN(SUBSTITUTE(AJ12,"/",""))+1) -> 0
W13: =IF($C13="","",SUMPRODUCT(($C$2:C13=C13)+($D$2:D13=C13))) | X13: =IF($D13="","",SUMPRODUCT(($C$2:C13=D13)+($D$2:D13=D13))) | Y13: =IF($C13="","",C13&"|"&W13) | Z13: =IF($D13="","",D13&"|"&X13) | AA13: =IF($C13="","",IF(COUNTIF($C$1:C12,$C13)+COUNTIF($D$1:D12,$C13)=0,1,0)) | AB13: =IF($D13="","",IF(COUNTIF($C$1:C13,$D13)+COUNTIF($D$1:D12,$D13)=0,1,0)) | AC13: =IF(AA13=1,SUM($AA$2:AA13)-AA13+SUM($AB$2:AB13)-AB13+1,"") | AD13: =IF(AB13=1,SUM($AA$2:AA13)+SUM($AB$2:AB13)-AB13+1,"") | AE13: =IF(AC13="","","TEAM|"&AC13) | AF13: =IF(AD13="","","TEAM|"&AD13) | AG13: =IF(AH13="",0,LEN(AH13)-LEN(SUBSTITUTE(AH13,"/",""))+1) -> 0 | AI13: =IF(AJ13="",0,LEN(AJ13)-LEN(SUBSTITUTE(AJ13,"/",""))+1) -> 0
W14: =IF($C14="","",SUMPRODUCT(($C$2:C14=C14)+($D$2:D14=C14))) | X14: =IF($D14="","",SUMPRODUCT(($C$2:C14=D14)+($D$2:D14=D14))) | Y14: =IF($C14="","",C14&"|"&W14) | Z14: =IF($D14="","",D14&"|"&X14) | AA14: =IF($C14="","",IF(COUNTIF($C$1:C13,$C14)+COUNTIF($D$1:D13,$C14)=0,1,0)) | AB14: =IF($D14="","",IF(COUNTIF($C$1:C14,$D14)+COUNTIF($D$1:D13,$D14)=0,1,0)) | AC14: =IF(AA14=1,SUM($AA$2:AA14)-AA14+SUM($AB$2:AB14)-AB14+1,"") | AD14: =IF(AB14=1,SUM($AA$2:AA14)+SUM($AB$2:AB14)-AB14+1,"") | AE14: =IF(AC14="","","TEAM|"&AC14) | AF14: =IF(AD14="","","TEAM|"&AD14) | AG14: =IF(AH14="",0,LEN(AH14)-LEN(SUBSTITUTE(AH14,"/",""))+1) -> 0 | AI14: =IF(AJ14="",0,LEN(AJ14)-LEN(SUBSTITUTE(AJ14,"/",""))+1) -> 0
W15: =IF($C15="","",SUMPRODUCT(($C$2:C15=C15)+($D$2:D15=C15))) | X15: =IF($D15="","",SUMPRODUCT(($C$2:C15=D15)+($D$2:D15=D15))) | Y15: =IF($C15="","",C15&"|"&W15) | Z15: =IF($D15="","",D15&"|"&X15) | AA15: =IF($C15="","",IF(COUNTIF($C$1:C14,$C15)+COUNTIF($D$1:D14,$C15)=0,1,0)) | AB15: =IF($D15="","",IF(COUNTIF($C$1:C15,$D15)+COUNTIF($D$1:D14,$D15)=0,1,0)) | AC15: =IF(AA15=1,SUM($AA$2:AA15)-AA15+SUM($AB$2:AB15)-AB15+1,"") | AD15: =IF(AB15=1,SUM($AA$2:AA15)+SUM($AB$2:AB15)-AB15+1,"") | AE15: =IF(AC15="","","TEAM|"&AC15) | AF15: =IF(AD15="","","TEAM|"&AD15) | AG15: =IF(AH15="",0,LEN(AH15)-LEN(SUBSTITUTE(AH15,"/",""))+1) -> 0 | AI15: =IF(AJ15="",0,LEN(AJ15)-LEN(SUBSTITUTE(AJ15,"/",""))+1) -> 0
W16: =IF($C16="","",SUMPRODUCT(($C$2:C16=C16)+($D$2:D16=C16))) | X16: =IF($D16="","",SUMPRODUCT(($C$2:C16=D16)+($D$2:D16=D16))) | Y16: =IF($C16="","",C16&"|"&W16) | Z16: =IF($D16="","",D16&"|"&X16) | AA16: =IF($C16="","",IF(COUNTIF($C$1:C15,$C16)+COUNTIF($D$1:D15,$C16)=0,1,0)) | AB16: =IF($D16="","",IF(COUNTIF($C$1:C16,$D16)+COUNTIF($D$1:D15,$D16)=0,1,0)) | AC16: =IF(AA16=1,SUM($AA$2:AA16)-AA16+SUM($AB$2:AB16)-AB16+1,"") | AD16: =IF(AB16=1,SUM($AA$2:AA16)+SUM($AB$2:AB16)-AB16+1,"") | AE16: =IF(AC16="","","TEAM|"&AC16) | AF16: =IF(AD16="","","TEAM|"&AD16) | AG16: =IF(AH16="",0,LEN(AH16)-LEN(SUBSTITUTE(AH16,"/",""))+1) -> 0 | AI16: =IF(AJ16="",0,LEN(AJ16)-LEN(SUBSTITUTE(AJ16,"/",""))+1) -> 0
W17: =IF($C17="","",SUMPRODUCT(($C$2:C17=C17)+($D$2:D17=C17))) | X17: =IF($D17="","",SUMPRODUCT(($C$2:C17=D17)+($D$2:D17=D17))) | Y17: =IF($C17="","",C17&"|"&W17) | Z17: =IF($D17="","",D17&"|"&X17) | AA17: =IF($C17="","",IF(COUNTIF($C$1:C16,$C17)+COUNTIF($D$1:D16,$C17)=0,1,0)) | AB17: =IF($D17="","",IF(COUNTIF($C$1:C17,$D17)+COUNTIF($D$1:D16,$D17)=0,1,0)) | AC17: =IF(AA17=1,SUM($AA$2:AA17)-AA17+SUM($AB$2:AB17)-AB17+1,"") | AD17: =IF(AB17=1,SUM($AA$2:AA17)+SUM($AB$2:AB17)-AB17+1,"") | AE17: =IF(AC17="","","TEAM|"&AC17) | AF17: =IF(AD17="","","TEAM|"&AD17) | AG17: =IF(AH17="",0,LEN(AH17)-LEN(SUBSTITUTE(AH17,"/",""))+1) -> 0 | AI17: =IF(AJ17="",0,LEN(AJ17)-LEN(SUBSTITUTE(AJ17,"/",""))+1) -> 0
W18: =IF($C18="","",SUMPRODUCT(($C$2:C18=C18)+($D$2:D18=C18))) | X18: =IF($D18="","",SUMPRODUCT(($C$2:C18=D18)+($D$2:D18=D18))) | Y18: =IF($C18="","",C18&"|"&W18) | Z18: =IF($D18="","",D18&"|"&X18) | AA18: =IF($C18="","",IF(COUNTIF($C$1:C17,$C18)+COUNTIF($D$1:D17,$C18)=0,1,0)) | AB18: =IF($D18="","",IF(COUNTIF($C$1:C18,$D18)+COUNTIF($D$1:D17,$D18)=0,1,0)) | AC18: =IF(AA18=1,SUM($AA$2:AA18)-AA18+SUM($AB$2:AB18)-AB18+1,"") | AD18: =IF(AB18=1,SUM($AA$2:AA18)+SUM($AB$2:AB18)-AB18+1,"") | AE18: =IF(AC18="","","TEAM|"&AC18) | AF18: =IF(AD18="","","TEAM|"&AD18) | AG18: =IF(AH18="",0,LEN(AH18)-LEN(SUBSTITUTE(AH18,"/",""))+1) -> 0 | AI18: =IF(AJ18="",0,LEN(AJ18)-LEN(SUBSTITUTE(AJ18,"/",""))+1) -> 0
W19: =IF($C19="","",SUMPRODUCT(($C$2:C19=C19)+($D$2:D19=C19))) | X19: =IF($D19="","",SUMPRODUCT(($C$2:C19=D19)+($D$2:D19=D19))) | Y19: =IF($C19="","",C19&"|"&W19) | Z19: =IF($D19="","",D19&"|"&X19) | AA19: =IF($C19="","",IF(COUNTIF($C$1:C18,$C19)+COUNTIF($D$1:D18,$C19)=0,1,0)) | AB19: =IF($D19="","",IF(COUNTIF($C$1:C19,$D19)+COUNTIF($D$1:D18,$D19)=0,1,0)) | AC19: =IF(AA19=1,SUM($AA$2:AA19)-AA19+SUM($AB$2:AB19)-AB19+1,"") | AD19: =IF(AB19=1,SUM($AA$2:AA19)+SUM($AB$2:AB19)-AB19+1,"") | AE19: =IF(AC19="","","TEAM|"&AC19) | AF19: =IF(AD19="","","TEAM|"&AD19) | AG19: =IF(AH19="",0,LEN(AH19)-LEN(SUBSTITUTE(AH19,"/",""))+1) -> 0 | AI19: =IF(AJ19="",0,LEN(AJ19)-LEN(SUBSTITUTE(AJ19,"/",""))+1) -> 0
W20: =IF($C20="","",SUMPRODUCT(($C$2:C20=C20)+($D$2:D20=C20))) | X20: =IF($D20="","",SUMPRODUCT(($C$2:C20=D20)+($D$2:D20=D20))) | Y20: =IF($C20="","",C20&"|"&W20) | Z20: =IF($D20="","",D20&"|"&X20) | AA20: =IF($C20="","",IF(COUNTIF($C$1:C19,$C20)+COUNTIF($D$1:D19,$C20)=0,1,0)) | AB20: =IF($D20="","",IF(COUNTIF($C$1:C20,$D20)+COUNTIF($D$1:D19,$D20)=0,1,0)) | AC20: =IF(AA20=1,SUM($AA$2:AA20)-AA20+SUM($AB$2:AB20)-AB20+1,"") | AD20: =IF(AB20=1,SUM($AA$2:AA20)+SUM($AB$2:AB20)-AB20+1,"") | AE20: =IF(AC20="","","TEAM|"&AC20) | AF20: =IF(AD20="","","TEAM|"&AD20) | AG20: =IF(AH20="",0,LEN(AH20)-LEN(SUBSTITUTE(AH20,"/",""))+1) -> 0 | AI20: =IF(AJ20="",0,LEN(AJ20)-LEN(SUBSTITUTE(AJ20,"/",""))+1) -> 0
W21: =IF($C21="","",SUMPRODUCT(($C$2:C21=C21)+($D$2:D21=C21))) | X21: =IF($D21="","",SUMPRODUCT(($C$2:C21=D21)+($D$2:D21=D21))) | Y21: =IF($C21="","",C21&"|"&W21) | Z21: =IF($D21="","",D21&"|"&X21) | AA21: =IF($C21="","",IF(COUNTIF($C$1:C20,$C21)+COUNTIF($D$1:D20,$C21)=0,1,0)) | AB21: =IF($D21="","",IF(COUNTIF($C$1:C21,$D21)+COUNTIF($D$1:D20,$D21)=0,1,0)) | AC21: =IF(AA21=1,SUM($AA$2:AA21)-AA21+SUM($AB$2:AB21)-AB21+1,"") | AD21: =IF(AB21=1,SUM($AA$2:AA21)+SUM($AB$2:AB21)-AB21+1,"") | AE21: =IF(AC21="","","TEAM|"&AC21) | AF21: =IF(AD21="","","TEAM|"&AD21) | AG21: =IF(AH21="",0,LEN(AH21)-LEN(SUBSTITUTE(AH21,"/",""))+1) -> 0 | AI21: =IF(AJ21="",0,LEN(AJ21)-LEN(SUBSTITUTE(AJ21,"/",""))+1) -> 0
W22: =IF($C22="","",SUMPRODUCT(($C$2:C22=C22)+($D$2:D22=C22))) | X22: =IF($D22="","",SUMPRODUCT(($C$2:C22=D22)+($D$2:D22=D22))) | Y22: =IF($C22="","",C22&"|"&W22) | Z22: =IF($D22="","",D22&"|"&X22) | AA22: =IF($C22="","",IF(COUNTIF($C$1:C21,$C22)+COUNTIF($D$1:D21,$C22)=0,1,0)) | AB22: =IF($D22="","",IF(COUNTIF($C$1:C22,$D22)+COUNTIF($D$1:D21,$D22)=0,1,0)) | AC22: =IF(AA22=1,SUM($AA$2:AA22)-AA22+SUM($AB$2:AB22)-AB22+1,"") | AD22: =IF(AB22=1,SUM($AA$2:AA22)+SUM($AB$2:AB22)-AB22+1,"") | AE22: =IF(AC22="","","TEAM|"&AC22) | AF22: =IF(AD22="","","TEAM|"&AD22) | AG22: =IF(AH22="",0,LEN(AH22)-LEN(SUBSTITUTE(AH22,"/",""))+1) -> 0 | AI22: =IF(AJ22="",0,LEN(AJ22)-LEN(SUBSTITUTE(AJ22,"/",""))+1) -> 0
... W1001: =IF($C1001="","",SUMPRODUCT(($C$2:C1001=C1001)+($D$2:D1001=C1001))) | X1001: =IF($D1001="","",SUMPRODUCT(($C$2:C1001=D1001)+($D$2:D1001=D1001))) | Y1001: =IF($C1001="","",C1001&"|"&W1001) | Z1001: =IF($D1001="","",D1001&"|"&X1001) | AA1001: =IF($C1001="","",IF(COUNTIF($C$1:C1000,$C1001)+COUNTIF($D$1:D1000,$C1001)=0,1,0)) | AB1001: =IF($D1001="","",IF(COUNTIF($C$1:C1001,$D1001)+COUNTIF($D$1:D1000,$D1001)=0,1,0)) | AC1001: =IF(AA1001=1,SUM($AA$2:AA1001)-AA1001+SUM($AB$2:AB1001)-AB1001+1,"") | AD1001: =IF(AB1001=1,SUM($AA$2:AA1001)+SUM($AB$2:AB1001)-AB1001+1,"") | AE1001: =IF(AC1001="","","TEAM|"&AC1001) | AF1001: =IF(AD1001="","","TEAM|"&AD1001) | AG1001: =IF(AH1001="",0,LEN(AH1001)-LEN(SUBSTITUTE(AH1001,"/",""))+1) -> 0 | AI1001: =IF(AJ1001="",0,LEN(AJ1001)-LEN(SUBSTITUTE(AJ1001,"/",""))+1) -> 0
AG1002: =IF(AH1002="",0,LEN(AH1002)-LEN(SUBSTITUTE(AH1002,"/",""))+1) -> 0 | AI1002: =IF(AJ1002="",0,LEN(AJ1002)-LEN(SUBSTITUTE(AJ1002,"/",""))+1) -> 0
AG1003: =IF(AH1003="",0,LEN(AH1003)-LEN(SUBSTITUTE(AH1003,"/",""))+1) -> 0 | AI1003: =IF(AJ1003="",0,LEN(AJ1003)-LEN(SUBSTITUTE(AJ1003,"/",""))+1) -> 0
AG1004: =IF(AH1004="",0,LEN(AH1004)-LEN(SUBSTITUTE(AH1004,"/",""))+1) -> 0 | AI1004: =IF(AJ1004="",0,LEN(AJ1004)-LEN(SUBSTITUTE(AJ1004,"/",""))+1) -> 0
AG1005: =IF(AH1005="",0,LEN(AH1005)-LEN(SUBSTITUTE(AH1005,"/",""))+1) -> 0 | AI1005: =IF(AJ1005="",0,LEN(AJ1005)-LEN(SUBSTITUTE(AJ1005,"/",""))+1) -> 0
AG1006: =IF(AH1006="",0,LEN(AH1006)-LEN(SUBSTITUTE(AH1006,"/",""))+1) -> 0 | AI1006: =IF(AJ1006="",0,LEN(AJ1006)-LEN(SUBSTITUTE(AJ1006,"/",""))+1) -> 0
AG1007: =IF(AH1007="",0,LEN(AH1007)-LEN(SUBSTITUTE(AH1007,"/",""))+1) -> 0 | AI1007: =IF(AJ1007="",0,LEN(AJ1007)-LEN(SUBSTITUTE(AJ1007,"/",""))+1) -> 0
AG1008: =IF(AH1008="",0,LEN(AH1008)-LEN(SUBSTITUTE(AH1008,"/",""))+1) -> 0 | AI1008: =IF(AJ1008="",0,LEN(AJ1008)-LEN(SUBSTITUTE(AJ1008,"/",""))+1) -> 0
AG1009: =IF(AH1009="",0,LEN(AH1009)-LEN(SUBSTITUTE(AH1009,"/",""))+1) -> 0 | AI1009: =IF(AJ1009="",0,LEN(AJ1009)-LEN(SUBSTITUTE(AJ1009,"/",""))+1) -> 0
AG1010: =IF(AH1010="",0,LEN(AH1010)-LEN(SUBSTITUTE(AH1010,"/",""))+1) -> 0 | AI1010: =IF(AJ1010="",0,LEN(AJ1010)-LEN(SUBSTITUTE(AJ1010,"/",""))+1) -> 0
AG1011: =IF(AH1011="",0,LEN(AH1011)-LEN(SUBSTITUTE(AH1011,"/",""))+1) -> 0 | AI1011: =IF(AJ1011="",0,LEN(AJ1011)-LEN(SUBSTITUTE(AJ1011,"/",""))+1) -> 0
AG1012: =IF(AH1012="",0,LEN(AH1012)-LEN(SUBSTITUTE(AH1012,"/",""))+1) -> 0 | AI1012: =IF(AJ1012="",0,LEN(AJ1012)-LEN(SUBSTITUTE(AJ1012,"/",""))+1) -> 0
AG1013: =IF(AH1013="",0,LEN(AH1013)-LEN(SUBSTITUTE(AH1013,"/",""))+1) -> 0 | AI1013: =IF(AJ1013="",0,LEN(AJ1013)-LEN(SUBSTITUTE(AJ1013,"/",""))+1) -> 0
... AG1401: =IF(AH1401="",0,LEN(AH1401)-LEN(SUBSTITUTE(AH1401,"/",""))+1) -> 0 | AI1401: =IF(AJ1401="",0,LEN(AJ1401)-LEN(SUBSTITUTE(AJ1401,"/",""))+1) -> 0

Sheet Tabla Posiciones
A1: Pos | B1: Equipo | C1: PJ | D1: PG | E1: PE | F1: PP | G1: GF | H1: GC | I1: DG | J1: PTS | K1: Últimos 5 | M1: Aux: últimos 5 (no editar) | N1: CALC (no editar)
A2: =IF(COUNT($X$2:$X$61)>=1,1,"") -> 1 | B2: =IF($A2="","",INDEX($N$2:$N$61,MATCH($A2,$X$2:$X$61,0))) -> Pachuca | C2: =IF($A2="","",INDEX($O$2:$O$61,MATCH($A2,$X$2:$X$61,0))) -> 1 | D2: =IF($A2="","",INDEX($P$2:$P$61,MATCH($A2,$X$2:$X$61,0))) -> 1 | E2: =IF($A2="","",INDEX($Q$2:$Q$61,MATCH($A2,$X$2:$X$61,0))) -> 0 | F2: =IF($A2="","",INDEX($R$2:$R$61,MATCH($A2,$X$2:$X$61,0))) -> 0 | G2: =IF($A2="","",INDEX($S$2:$S$61,MATCH($A2,$X$2:$X$61,0))) -> 3 | H2: =IF($A2="","",INDEX($T$2:$T$61,MATCH($A2,$X$2:$X$61,0))) -> 0 | I2: =IF($A2="","",INDEX($U$2:$U$61,MATCH($A2,$X$2:$X$61,0))) -> 3 | J2: =IF($A2="","",INDEX($V$2:$V$61,MATCH($A2,$X$2:$X$61,0))) -> 3 | K2: =IF($A2="","",INDEX($AN$2:$AN$61,MATCH($A2,$X$2:$X$61,0))) -> V | N2: =IFERROR(INDEX(Partidos!$C$2:$C$1401,MATCH("TEAM|1",Partidos!$AE$2:$AE$1401,0)),IFERROR(INDEX(Partidos!$D$2:$D$1401,MATCH("TEAM|1",Partidos!$AF$2:$AF$1401,0)),"")) -> Necaxa | O2: =IF(N2="","",COUNTIF(Partidos!$C$2:$C$1401,N2)+COUNTIF(Partidos!$D$2:$D$1401,N2)) -> 1 | P2: =IF(N2="","",SUMPRODUCT((Partidos!$C$2:$C$1401=N2)*(Partidos!$E$2:$E$1401>Partidos!$F$2:$F$1401))+SUMPRODUCT((Partidos!$D$2:$D$1401=N2)*(Partidos!$F$2:$F$1401>Partidos!$E$2:$E$1401))) -> 1 | Q2: =IF(N2="","",SUMPRODUCT((((Partidos!$C$2:$C$1401=N2)+(Partidos!$D$2:$D$1401=N2)))*(Partidos!$E$2:$E$1401=Partidos!$F$2:$F$1401)*(Partidos!$C$2:$C$1401<>""))) -> 0 | R2: =IF(N2="","",O2-P2-Q2) -> 0 | S2: =IF(N2="","",SUMIF(Partidos!$C$2:$C$1401,N2,Partidos!$E$2:$E$1401)+SUMIF(Partidos!$D$2:$D$1401,N2,Partidos!$F$2:$F$1401)) -> 2 | T2: =IF(N2="","",SUMIF(Partidos!$C$2:$C$1401,N2,Partidos!$F$2:$F$1401)+SUMIF(Partidos!$D$2:$D$1401,N2,Partidos!$E$2:$E$1401)) -> 1 | U2: =IF(N2="","",S2-T2) -> 1 | V2: =IF(N2="","",P2*3+Q2) -> 3 | W2: =IF(N2="","",V2*1000000+U2*1000+S2+(ROW()*0.0000001)) -> 3001002 | X2: =IF(N2="","",RANK(W2,$W$2:$W$61)) -> 7 | Y2: =IF(N2="","",O2-4) -> -3 | Z2: =IF(N2="","",O2-3) -> -2 | AA2: =IF(N2="","",O2-2) -> -1 | AB2: =IF(N2="","",O2-1) -> 0 | AC2: =IF(N2="","",O2-0) -> 1 | AD2: =IF(OR(N2="",Y2=""),"",IF(Y2<1,"",IFERROR(MATCH($N2&"|"&Y2,Partidos!$Y:$Y,0),IFERROR(MATCH($N2&"|"&Y2,Partidos!$Z:$Z,0),"")))) | AE2: =IF(OR(N2="",Z2=""),"",IF(Z2<1,"",IFERROR(MATCH($N2&"|"&Z2,Partidos!$Y:$Y,0),IFERROR(MATCH($N2&"|"&Z2,Partidos!$Z:$Z,0),"")))) | AF2: =IF(OR(N2="",AA2=""),"",IF(AA2<1,"",IFERROR(MATCH($N2&"|"&AA2,Partidos!$Y:$Y,0),IFERROR(MATCH($N2&"|"&AA2,Partidos!$Z:$Z,0),"")))) | AG2: =IF(OR(N2="",AB2=""),"",IF(AB2<1,"",IFERROR(MATCH($N2&"|"&AB2,Partidos!$Y:$Y,0),IFERROR(MATCH($N2&"|"&AB2,Partidos!$Z:$Z,0),"")))) | AH2: =IF(OR(N2="",AC2=""),"",IF(AC2<1,"",IFERROR(MATCH($N2&"|"&AC2,Partidos!$Y:$Y,0),IFERROR(MATCH($N2&"|"&AC2,Partidos!$Z:$Z,0),"")))) -> 2 | AI2: =IF(AD2="","",IF(INDEX(Partidos!$C:$C,AD2)=$N2,IF(INDEX(Partidos!$E:$E,AD2)>INDEX(Partidos!$F:$F,AD2),"V",IF(INDEX(Partidos!$E:$E,AD2)=INDEX(Partidos!$F:$F,AD2),"E","P")),IF(INDEX(Partidos!$F:$F,AD2)>INDEX(Partidos!$E:$E,AD2),"V",IF(INDEX(Partidos!$F:$F,AD2)=INDEX(Partidos!$E:$E,AD2),"E","P")))) | AJ2: =IF(AE2="","",IF(INDEX(Partidos!$C:$C,AE2)=$N2,IF(INDEX(Partidos!$E:$E,AE2)>INDEX(Partidos!$F:$F,AE2),"V",IF(INDEX(Partidos!$E:$E,AE2)=INDEX(Partidos!$F:$F,AE2),"E","P")),IF(INDEX(Partidos!$F:$F,AE2)>INDEX(Partidos!$E:$E,AE2),"V",IF(INDEX(Partidos!$F:$F,AE2)=INDEX(Partidos!$E:$E,AE2),"E","P")))) | AK2: =IF(AF2="","",IF(INDEX(Partidos!$C:$C,AF2)=$N2,IF(INDEX(Partidos!$E:$E,AF2)>INDEX(Partidos!$F:$F,AF2),"V",IF(INDEX(Partidos!$E:$E,AF2)=INDEX(Partidos!$F:$F,AF2),"E","P")),IF(INDEX(Partidos!$F:$F,AF2)>INDEX(Partidos!$E:$E,AF2),"V",IF(INDEX(Partidos!$F:$F,AF2)=INDEX(Partidos!$E:$E,AF2),"E","P")))) | AL2: =IF(AG2="","",IF(INDEX(Partidos!$C:$C,AG2)=$N2,IF(INDEX(Partidos!$E:$E,AG2)>INDEX(Partidos!$F:$F,AG2),"V",IF(INDEX(Partidos!$E:$E,AG2)=INDEX(Partidos!$F:$F,AG2),"E","P")),IF(INDEX(Partidos!$F:$F,AG2)>INDEX(Partidos!$E:$E,AG2),"V",IF(INDEX(Partidos!$F:$F,AG2)=INDEX(Partidos!$E:$E,AG2),"E","P")))) | AM2: =IF(AH2="","",IF(INDEX(Partidos!$C:$C,AH2)=$N2,IF(INDEX(Partidos!$E:$E,AH2)>INDEX(Partidos!$F:$F,AH2),"V",IF(INDEX(Partidos!$E:$E,AH2)=INDEX(Partidos!$F:$F,AH2),"E","P")),IF(INDEX(Partidos!$F:$F,AH2)>INDEX(Partidos!$E:$E,AH2),"V",IF(INDEX(Partidos!$F:$F,AH2)=INDEX(Partidos!$E:$E,AH2),"E","P")))) -> V | AN2: =IF(N2="","",_xlfn.TEXTJOIN("-",TRUE(),AI2:AM2)) -> V | AO2: =IF(N2="","",RANK(S2,$S$2:$S$61,0)) -> 6 | AP2: =IF(AO2=1,SUMPRODUCT(($AO$2:AO2=1)*1),"") | AQ2: =IF(AO2=1,"GF|"&AP2,"") | AR2: =IF(N2="","",RANK(T2,$T$2:$T$61,1)) -> 5 | AS2: =IF(AR2=1,SUMPRODUCT(($AR$2:AR2=1)*1),"") | AT2: =IF(AR2=1,"GC|"&AS2,"")
A3: =IF(COUNT($X$2:$X$61)>=2,2,"") -> 2 | B3: =IF($A3="","",INDEX($N$2:$N$61,MATCH($A3,$X$2:$X$61,0))) -> Tijuana | C3: =IF($A3="","",INDEX($O$2:$O$61,MATCH($A3,$X$2:$X$61,0))) -> 1 | D3: =IF($A3="","",INDEX($P$2:$P$61,MATCH($A3,$X$2:$X$61,0))) -> 1 | E3: =IF($A3="","",INDEX($Q$2:$Q$61,MATCH($A3,$X$2:$X$61,0))) -> 0 | F3: =IF($A3="","",INDEX($R$2:$R$61,MATCH($A3,$X$2:$X$61,0))) -> 0 | G3: =IF($A3="","",INDEX($S$2:$S$61,MATCH($A3,$X$2:$X$61,0))) -> 3 | H3: =IF($A3="","",INDEX($T$2:$T$61,MATCH($A3,$X$2:$X$61,0))) -> 1 | I3: =IF($A3="","",INDEX($U$2:$U$61,MATCH($A3,$X$2:$X$61,0))) -> 2 | J3: =IF($A3="","",INDEX($V$2:$V$61,MATCH($A3,$X$2:$X$61,0))) -> 3 | K3: =IF($A3="","",INDEX($AN$2:$AN$61,MATCH($A3,$X$2:$X$61,0))) -> V | N3: =IFERROR(INDEX(Partidos!$C$2:$C$1401,MATCH("TEAM|2",Partidos!$AE$2:$AE$1401,0)),IFERROR(INDEX(Partidos!$D$2:$D$1401,MATCH("TEAM|2",Partidos!$AF$2:$AF$1401,0)),"")) -> Atlante | O3: =IF(N3="","",COUNTIF(Partidos!$C$2:$C$1401,N3)+COUNTIF(Partidos!$D$2:$D$1401,N3)) -> 1 | P3: =IF(N3="","",SUMPRODUCT((Partidos!$C$2:$C$1401=N3)*(Partidos!$E$2:$E$1401>Partidos!$F$2:$F$1401))+SUMPRODUCT((Partidos!$D$2:$D$1401=N3)*(Partidos!$F$2:$F$1401>Partidos!$E$2:$E$1401))) -> 0 | Q3: =IF(N3="","",SUMPRODUCT((((Partidos!$C$2:$C$1401=N3)+(Partidos!$D$2:$D$1401=N3)))*(Partidos!$E$2:$E$1401=Partidos!$F$2:$F$1401)*(Partidos!$C$2:$C$1401<>""))) -> 0 | R3: =IF(N3="","",O3-P3-Q3) -> 1 | S3: =IF(N3="","",SUMIF(Partidos!$C$2:$C$1401,N3,Partidos!$E$2:$E$1401)+SUMIF(Partidos!$D$2:$D$1401,N3,Partidos!$F$2:$F$1401)) -> 1 | T3: =IF(N3="","",SUMIF(Partidos!$C$2:$C$1401,N3,Partidos!$F$2:$F$1401)+SUMIF(Partidos!$D$2:$D$1401,N3,Partidos!$E$2:$E$1401)) -> 2 | U3: =IF(N3="","",S3-T3) -> -1 | V3: =IF(N3="","",P3*3+Q3) -> 0 | W3: =IF(N3="","",V3*1000000+U3*1000+S3+(ROW()*0.0000001)) -> -999 | X3: =IF(N3="","",RANK(W3,$W$2:$W$61)) -> 13 | Y3: =IF(N3="","",O3-4) -> -3 | Z3: =IF(N3="","",O3-3) -> -2 | AA3: =IF(N3="","",O3-2) -> -1 | AB3: =IF(N3="","",O3-1) -> 0 | AC3: =IF(N3="","",O3-0) -> 1 | AD3: =IF(OR(N3="",Y3=""),"",IF(Y3<1,"",IFERROR(MATCH($N3&"|"&Y3,Partidos!$Y:$Y,0),IFERROR(MATCH($N3&"|"&Y3,Partidos!$Z:$Z,0),"")))) | AE3: =IF(OR(N3="",Z3=""),"",IF(Z3<1,"",IFERROR(MATCH($N3&"|"&Z3,Partidos!$Y:$Y,0),IFERROR(MATCH($N3&"|"&Z3,Partidos!$Z:$Z,0),"")))) | AF3: =IF(OR(N3="",AA3=""),"",IF(AA3<1,"",IFERROR(MATCH($N3&"|"&AA3,Partidos!$Y:$Y,0),IFERROR(MATCH($N3&"|"&AA3,Partidos!$Z:$Z,0),"")))) | AG3: =IF(OR(N3="",AB3=""),"",IF(AB3<1,"",IFERROR(MATCH($N3&"|"&AB3,Partidos!$Y:$Y,0),IFERROR(MATCH($N3&"|"&AB3,Partidos!$Z:$Z,0),"")))) | AH3: =IF(OR(N3="",AC3=""),"",IF(AC3<1,"",IFERROR(MATCH($N3&"|"&AC3,Partidos!$Y:$Y,0),IFERROR(MATCH($N3&"|"&AC3,Partidos!$Z:$Z,0),"")))) -> 2 | AI3: =IF(AD3="","",IF(INDEX(Partidos!$C:$C,AD3)=$N3,IF(INDEX(Partidos!$E:$E,AD3)>INDEX(Partidos!$F:$F,AD3),"V",IF(INDEX(Partidos!$E:$E,AD3)=INDEX(Partidos!$F:$F,AD3),"E","P")),IF(INDEX(Partidos!$F:$F,AD3)>INDEX(Partidos!$E:$E,AD3),"V",IF(INDEX(Partidos!$F:$F,AD3)=INDEX(Partidos!$E:$E,AD3),"E","P")))) | AJ3: =IF(AE3="","",IF(INDEX(Partidos!$C:$C,AE3)=$N3,IF(INDEX(Partidos!$E:$E,AE3)>INDEX(Partidos!$F:$F,AE3),"V",IF(INDEX(Partidos!$E:$E,AE3)=INDEX(Partidos!$F:$F,AE3),"E","P")),IF(INDEX(Partidos!$F:$F,AE3)>INDEX(Partidos!$E:$E,AE3),"V",IF(INDEX(Partidos!$F:$F,AE3)=INDEX(Partidos!$E:$E,AE3),"E","P")))) | AK3: =IF(AF3="","",IF(INDEX(Partidos!$C:$C,AF3)=$N3,IF(INDEX(Partidos!$E:$E,AF3)>INDEX(Partidos!$F:$F,AF3),"V",IF(INDEX(Partidos!$E:$E,AF3)=INDEX(Partidos!$F:$F,AF3),"E","P")),IF(INDEX(Partidos!$F:$F,AF3)>INDEX(Partidos!$E:$E,AF3),"V",IF(INDEX(Partidos!$F:$F,AF3)=INDEX(Partidos!$E:$E,AF3),"E","P")))) | AL3: =IF(AG3="","",IF(INDEX(Partidos!$C:$C,AG3)=$N3,IF(INDEX(Partidos!$E:$E,AG3)>INDEX(Partidos!$F:$F,AG3),"V",IF(INDEX(Partidos!$E:$E,AG3)=INDEX(Partidos!$F:$F,AG3),"E","P")),IF(INDEX(Partidos!$F:$F,AG3)>INDEX(Partidos!$E:$E,AG3),"V",IF(INDEX(Partidos!$F:$F,AG3)=INDEX(Partidos!$E:$E,AG3),"E","P")))) | AM3: =IF(AH3="","",IF(INDEX(Partidos!$C:$C,AH3)=$N3,IF(INDEX(Partidos!$E:$E,AH3)>INDEX(Partidos!$F:$F,AH3),"V",IF(INDEX(Partidos!$E:$E,AH3)=INDEX(Partidos!$F:$F,AH3),"E","P")),IF(INDEX(Partidos!$F:$F,AH3)>INDEX(Partidos!$E:$E,AH3),"V",IF(INDEX(Partidos!$F:$F,AH3)=INDEX(Partidos!$E:$E,AH3),"E","P")))) -> P | AN3: =IF(N3="","",_xlfn.TEXTJOIN("-",TRUE(),AI3:AM3)) -> P | AO3: =IF(N3="","",RANK(S3,$S$2:$S$61,0)) -> 11 | AP3: =IF(AO3=1,SUMPRODUCT(($AO$2:AO3=1)*1),"") | AQ3: =IF(AO3=1,"GF|"&AP3,"") | AR3: =IF(N3="","",RANK(T3,$T$2:$T$61,1)) -> 9 | AS3: =IF(AR3=1,SUMPRODUCT(($AR$2:AR3=1)*1),"") | AT3: =IF(AR3=1,"GC|"&AS3,"")
A4: =IF(COUNT($X$2:$X$61)>=3,3,"") -> 3 | B4: =IF($A4="","",INDEX($N$2:$N$61,MATCH($A4,$X$2:$X$61,0))) -> Toluca | C4: =IF($A4="","",INDEX($O$2:$O$61,MATCH($A4,$X$2:$X$61,0))) -> 1 | D4: =IF($A4="","",INDEX($P$2:$P$61,MATCH($A4,$X$2:$X$61,0))) -> 1 | E4: =IF($A4="","",INDEX($Q$2:$Q$61,MATCH($A4,$X$2:$X$61,0))) -> 0 | F4: =IF($A4="","",INDEX($R$2:$R$61,MATCH($A4,$X$2:$X$61,0))) -> 0 | G4: =IF($A4="","",INDEX($S$2:$S$61,MATCH($A4,$X$2:$X$61,0))) -> 2 | H4: =IF($A4="","",INDEX($T$2:$T$61,MATCH($A4,$X$2:$X$61,0))) -> 0 | I4: =IF($A4="","",INDEX($U$2:$U$61,MATCH($A4,$X$2:$X$61,0))) -> 2 | J4: =IF($A4="","",INDEX($V$2:$V$61,MATCH($A4,$X$2:$X$61,0))) -> 3 | K4: =IF($A4="","",INDEX($AN$2:$AN$61,MATCH($A4,$X$2:$X$61,0))) -> V | N4: =IFERROR(INDEX(Partidos!$C$2:$C$1401,MATCH("TEAM|3",Partidos!$AE$2:$AE$1401,0)),IFERROR(INDEX(Partidos!$D$2:$D$1401,MATCH("TEAM|3",Partidos!$AF$2:$AF$1401,0)),"")) -> Tijuana | O4: =IF(N4="","",COUNTIF(Partidos!$C$2:$C$1401,N4)+COUNTIF(Partidos!$D$2:$D$1401,N4)) -> 1 | P4: =IF(N4="","",SUMPRODUCT((Partidos!$C$2:$C$1401=N4)*(Partidos!$E$2:$E$1401>Partidos!$F$2:$F$1401))+SUMPRODUCT((Partidos!$D$2:$D$1401=N4)*(Partidos!$F$2:$F$1401>Partidos!$E$2:$E$1401))) -> 1 | Q4: =IF(N4="","",SUMPRODUCT((((Partidos!$C$2:$C$1401=N4)+(Partidos!$D$2:$D$1401=N4)))*(Partidos!$E$2:$E$1401=Partidos!$F$2:$F$1401)*(Partidos!$C$2:$C$1401<>""))) -> 0 | R4: =IF(N4="","",O4-P4-Q4) -> 0 | S4: =IF(N4="","",SUMIF(Partidos!$C$2:$C$1401,N4,Partidos!$E$2:$E$1401)+SUMIF(Partidos!$D$2:$D$1401,N4,Partidos!$F$2:$F$1401)) -> 3 | T4: =IF(N4="","",SUMIF(Partidos!$C$2:$C$1401,N4,Partidos!$F$2:$F$1401)+SUMIF(Partidos!$D$2:$D$1401,N4,Partidos!$E$2:$E$1401)) -> 1 | U4: =IF(N4="","",S4-T4) -> 2 | V4: =IF(N4="","",P4*3+Q4) -> 3 | W4: =IF(N4="","",V4*1000000+U4*1000+S4+(ROW()*0.0000001)) -> 3002003 | X4: =IF(N4="","",RANK(W4,$W$2:$W$61)) -> 2 | Y4: =IF(N4="","",O4-4) -> -3 | Z4: =IF(N4="","",O4-3) -> -2 | AA4: =IF(N4="","",O4-2) -> -1 | AB4: =IF(N4="","",O4-1) -> 0 | AC4: =IF(N4="","",O4-0) -> 1 | AD4: =IF(OR(N4="",Y4=""),"",IF(Y4<1,"",IFERROR(MATCH($N4&"|"&Y4,Partidos!$Y:$Y,0),IFERROR(MATCH($N4&"|"&Y4,Partidos!$Z:$Z,0),"")))) | AE4: =IF(OR(N4="",Z4=""),"",IF(Z4<1,"",IFERROR(MATCH($N4&"|"&Z4,Partidos!$Y:$Y,0),IFERROR(MATCH($N4&"|"&Z4,Partidos!$Z:$Z,0),"")))) | AF4: =IF(OR(N4="",AA4=""),"",IF(AA4<1,"",IFERROR(MATCH($N4&"|"&AA4,Partidos!$Y:$Y,0),IFERROR(MATCH($N4&"|"&AA4,Partidos!$Z:$Z,0),"")))) | AG4: =IF(OR(N4="",AB4=""),"",IF(AB4<1,"",IFERROR(MATCH($N4&"|"&AB4,Partidos!$Y:$Y,0),IFERROR(MATCH($N4&"|"&AB4,Partidos!$Z:$Z,0),"")))) | AH4: =IF(OR(N4="",AC4=""),"",IF(AC4<1,"",IFERROR(MATCH($N4&"|"&AC4,Partidos!$Y:$Y,0),IFERROR(MATCH($N4&"|"&AC4,Partidos!$Z:$Z,0),"")))) -> 3 | AI4: =IF(AD4="","",IF(INDEX(Partidos!$C:$C,AD4)=$N4,IF(INDEX(Partidos!$E:$E,AD4)>INDEX(Partidos!$F:$F,AD4),"V",IF(INDEX(Partidos!$E:$E,AD4)=INDEX(Partidos!$F:$F,AD4),"E","P")),IF(INDEX(Partidos!$F:$F,AD4)>INDEX(Partidos!$E:$E,AD4),"V",IF(INDEX(Partidos!$F:$F,AD4)=INDEX(Partidos!$E:$E,AD4),"E","P")))) | AJ4: =IF(AE4="","",IF(INDEX(Partidos!$C:$C,AE4)=$N4,IF(INDEX(Partidos!$E:$E,AE4)>INDEX(Partidos!$F:$F,AE4),"V",IF(INDEX(Partidos!$E:$E,AE4)=INDEX(Partidos!$F:$F,AE4),"E","P")),IF(INDEX(Partidos!$F:$F,AE4)>INDEX(Partidos!$E:$E,AE4),"V",IF(INDEX(Partidos!$F:$F,AE4)=INDEX(Partidos!$E:$E,AE4),"E","P")))) | AK4: =IF(AF4="","",IF(INDEX(Partidos!$C:$C,AF4)=$N4,IF(INDEX(Partidos!$E:$E,AF4)>INDEX(Partidos!$F:$F,AF4),"V",IF(INDEX(Partidos!$E:$E,AF4)=INDEX(Partidos!$F:$F,AF4),"E","P")),IF(INDEX(Partidos!$F:$F,AF4)>INDEX(Partidos!$E:$E,AF4),"V",IF(INDEX(Partidos!$F:$F,AF4)=INDEX(Partidos!$E:$E,AF4),"E","P")))) | AL4: =IF(AG4="","",IF(INDEX(Partidos!$C:$C,AG4)=$N4,IF(INDEX(Partidos!$E:$E,AG4)>INDEX(Partidos!$F:$F,AG4),"V",IF(INDEX(Partidos!$E:$E,AG4)=INDEX(Partidos!$F:$F,AG4),"E","P")),IF(INDEX(Partidos!$F:$F,AG4)>INDEX(Partidos!$E:$E,AG4),"V",IF(INDEX(Partidos!$F:$F,AG4)=INDEX(Partidos!$E:$E,AG4),"E","P")))) | AM4: =IF(AH4="","",IF(INDEX(Partidos!$C:$C,AH4)=$N4,IF(INDEX(Partidos!$E:$E,AH4)>INDEX(Partidos!$F:$F,AH4),"V",IF(INDEX(Partidos!$E:$E,AH4)=INDEX(Partidos!$F:$F,AH4),"E","P")),IF(INDEX(Partidos!$F:$F,AH4)>INDEX(Partidos!$E:$E,AH4),"V",IF(INDEX(Partidos!$F:$F,AH4)=INDEX(Partidos!$E:$E,AH4),"E","P")))) -> V | AN4: =IF(N4="","",_xlfn.TEXTJOIN("-",TRUE(),AI4:AM4)) -> V | AO4: =IF(N4="","",RANK(S4,$S$2:$S$61,0)) -> 1 | AP4: =IF(AO4=1,SUMPRODUCT(($AO$2:AO4=1)*1),"") -> 1 | AQ4: =IF(AO4=1,"GF|"&AP4,"") -> GF|1 | AR4: =IF(N4="","",RANK(T4,$T$2:$T$61,1)) -> 5 | AS4: =IF(AR4=1,SUMPRODUCT(($AR$2:AR4=1)*1),"") | AT4: =IF(AR4=1,"GC|"&AS4,"")
A5: =IF(COUNT($X$2:$X$61)>=4,4,"") -> 4 | B5: =IF($A5="","",INDEX($N$2:$N$61,MATCH($A5,$X$2:$X$61,0))) -> Monterrey | C5: =IF($A5="","",INDEX($O$2:$O$61,MATCH($A5,$X$2:$X$61,0))) -> 1 | D5: =IF($A5="","",INDEX($P$2:$P$61,MATCH($A5,$X$2:$X$61,0))) -> 1 | E5: =IF($A5="","",INDEX($Q$2:$Q$61,MATCH($A5,$X$2:$X$61,0))) -> 0 | F5: =IF($A5="","",INDEX($R$2:$R$61,MATCH($A5,$X$2:$X$61,0))) -> 0 | G5: =IF($A5="","",INDEX($S$2:$S$61,MATCH($A5,$X$2:$X$61,0))) -> 3 | H5: =IF($A5="","",INDEX($T$2:$T$61,MATCH($A5,$X$2:$X$61,0))) -> 2 | I5: =IF($A5="","",INDEX($U$2:$U$61,MATCH($A5,$X$2:$X$61,0))) -> 1 | J5: =IF($A5="","",INDEX($V$2:$V$61,MATCH($A5,$X$2:$X$61,0))) -> 3 | K5: =IF($A5="","",INDEX($AN$2:$AN$61,MATCH($A5,$X$2:$X$61,0))) -> V | N5: =IFERROR(INDEX(Partidos!$C$2:$C$1401,MATCH("TEAM|4",Partidos!$AE$2:$AE$1401,0)),IFERROR(INDEX(Partidos!$D$2:$D$1401,MATCH("TEAM|4",Partidos!$AF$2:$AF$1401,0)),"")) -> Tigres UANL | O5: =IF(N5="","",COUNTIF(Partidos!$C$2:$C$1401,N5)+COUNTIF(Partidos!$D$2:$D$1401,N5)) -> 1 | P5: =IF(N5="","",SUMPRODUCT((Partidos!$C$2:$C$1401=N5)*(Partidos!$E$2:$E$1401>Partidos!$F$2:$F$1401))+SUMPRODUCT((Partidos!$D$2:$D$1401=N5)*(Partidos!$F$2:$F$1401>Partidos!$E$2:$E$1401))) -> 0 | Q5: =IF(N5="","",SUMPRODUCT((((Partidos!$C$2:$C$1401=N5)+(Partidos!$D$2:$D$1401=N5)))*(Partidos!$E$2:$E$1401=Partidos!$F$2:$F$1401)*(Partidos!$C$2:$C$1401<>""))) -> 0 | R5: =IF(N5="","",O5-P5-Q5) -> 1 | S5: =IF(N5="","",SUMIF(Partidos!$C$2:$C$1401,N5,Partidos!$E$2:$E$1401)+SUMIF(Partidos!$D$2:$D$1401,N5,Partidos!$F$2:$F$1401)) -> 1 | T5: =IF(N5="","",SUMIF(Partidos!$C$2:$C$1401,N5,Partidos!$F$2:$F$1401)+SUMIF(Partidos!$D$2:$D$1401,N5,Partidos!$E$2:$E$1401)) -> 3 | U5: =IF(N5="","",S5-T5) -> -2 | V5: =IF(N5="","",P5*3+Q5) -> 0 | W5: =IF(N5="","",V5*1000000+U5*1000+S5+(ROW()*0.0000001)) -> -1999 | X5: =IF(N5="","",RANK(W5,$W$2:$W$61)) -> 16 | Y5: =IF(N5="","",O5-4) -> -3 | Z5: =IF(N5="","",O5-3) -> -2 | AA5: =IF(N5="","",O5-2) -> -1 | AB5: =IF(N5="","",O5-1) -> 0 | AC5: =IF(N5="","",O5-0) -> 1 | AD5: =IF(OR(N5="",Y5=""),"",IF(Y5<1,"",IFERROR(MATCH($N5&"|"&Y5,Partidos!$Y:$Y,0),IFERROR(MATCH($N5&"|"&Y5,Partidos!$Z:$Z,0),"")))) | AE5: =IF(OR(N5="",Z5=""),"",IF(Z5<1,"",IFERROR(MATCH($N5&"|"&Z5,Partidos!$Y:$Y,0),IFERROR(MATCH($N5&"|"&Z5,Partidos!$Z:$Z,0),"")))) | AF5: =IF(OR(N5="",AA5=""),"",IF(AA5<1,"",IFERROR(MATCH($N5&"|"&AA5,Partidos!$Y:$Y,0),IFERROR(MATCH($N5&"|"&AA5,Partidos!$Z:$Z,0),"")))) | AG5: =IF(OR(N5="",AB5=""),"",IF(AB5<1,"",IFERROR(MATCH($N5&"|"&AB5,Partidos!$Y:$Y,0),IFERROR(MATCH($N5&"|"&AB5,Partidos!$Z:$Z,0),"")))) | AH5: =IF(OR(N5="",AC5=""),"",IF(AC5<1,"",IFERROR(MATCH($N5&"|"&AC5,Partidos!$Y:$Y,0),IFERROR(MATCH($N5&"|"&AC5,Partidos!$Z:$Z,0),"")))) -> 3 | AI5: =IF(AD5="","",IF(INDEX(Partidos!$C:$C,AD5)=$N5,IF(INDEX(Partidos!$E:$E,AD5)>INDEX(Partidos!$F:$F,AD5),"V",IF(INDEX(Partidos!$E:$E,AD5)=INDEX(Partidos!$F:$F,AD5),"E","P")),IF(INDEX(Partidos!$F:$F,AD5)>INDEX(Partidos!$E:$E,AD5),"V",IF(INDEX(Partidos!$F:$F,AD5)=INDEX(Partidos!$E:$E,AD5),"E","P")))) | AJ5: =IF(AE5="","",IF(INDEX(Partidos!$C:$C,AE5)=$N5,IF(INDEX(Partidos!$E:$E,AE5)>INDEX(Partidos!$F:$F,AE5),"V",IF(INDEX(Partidos!$E:$E,AE5)=INDEX(Partidos!$F:$F,AE5),"E","P")),IF(INDEX(Partidos!$F:$F,AE5)>INDEX(Partidos!$E:$E,AE5),"V",IF(INDEX(Partidos!$F:$F,AE5)=INDEX(Partidos!$E:$E,AE5),"E","P")))) | AK5: =IF(AF5="","",IF(INDEX(Partidos!$C:$C,AF5)=$N5,IF(INDEX(Partidos!$E:$E,AF5)>INDEX(Partidos!$F:$F,AF5),"V",IF(INDEX(Partidos!$E:$E,AF5)=INDEX(Partidos!$F:$F,AF5),"E","P")),IF(INDEX(Partidos!$F:$F,AF5)>INDEX(Partidos!$E:$E,AF5),"V",IF(INDEX(Partidos!$F:$F,AF5)=INDEX(Partidos!$E:$E,AF5),"E","P")))) | AL5: =IF(AG5="","",IF(INDEX(Partidos!$C:$C,AG5)=$N5,IF(INDEX(Partidos!$E:$E,AG5)>INDEX(Partidos!$F:$F,AG5),"V",IF(INDEX(Partidos!$E:$E,AG5)=INDEX(Partidos!$F:$F,AG5),"E","P")),IF(INDEX(Partidos!$F:$F,AG5)>INDEX(Partidos!$E:$E,AG5),"V",IF(INDEX(Partidos!$F:$F,AG5)=INDEX(Partidos!$E:$E,AG5),"E","P")))) | AM5: =IF(AH5="","",IF(INDEX(Partidos!$C:$C,AH5)=$N5,IF(INDEX(Partidos!$E:$E,AH5)>INDEX(Partidos!$F:$F,AH5),"V",IF(INDEX(Partidos!$E:$E,AH5)=INDEX(Partidos!$F:$F,AH5),"E","P")),IF(INDEX(Partidos!$F:$F,AH5)>INDEX(Partidos!$E:$E,AH5),"V",IF(INDEX(Partidos!$F:$F,AH5)=INDEX(Partidos!$E:$E,AH5),"E","P")))) -> P | AN5: =IF(N5="","",_xlfn.TEXTJOIN("-",TRUE(),AI5:AM5)) -> P | AO5: =IF(N5="","",RANK(S5,$S$2:$S$61,0)) -> 11 | AP5: =IF(AO5=1,SUMPRODUCT(($AO$2:AO5=1)*1),"") | AQ5: =IF(AO5=1,"GF|"&AP5,"") | AR5: =IF(N5="","",RANK(T5,$T$2:$T$61,1)) -> 14 | AS5: =IF(AR5=1,SUMPRODUCT(($AR$2:AR5=1)*1),"") | AT5: =IF(AR5=1,"GC|"&AS5,"")
A6: =IF(COUNT($X$2:$X$61)>=5,5,"") -> 5 | B6: =IF($A6="","",INDEX($N$2:$N$61,MATCH($A6,$X$2:$X$61,0))) -> Cruz Azul | C6: =IF($A6="","",INDEX($O$2:$O$61,MATCH($A6,$X$2:$X$61,0))) -> 1 | D6: =IF($A6="","",INDEX($P$2:$P$61,MATCH($A6,$X$2:$X$61,0))) -> 1 | E6: =IF($A6="","",INDEX($Q$2:$Q$61,MATCH($A6,$X$2:$X$61,0))) -> 0 | F6: =IF($A6="","",INDEX($R$2:$R$61,MATCH($A6,$X$2:$X$61,0))) -> 0 | G6: =IF($A6="","",INDEX($S$2:$S$61,MATCH($A6,$X$2:$X$61,0))) -> 3 | H6: =IF($A6="","",INDEX($T$2:$T$61,MATCH($A6,$X$2:$X$61,0))) -> 2 | I6: =IF($A6="","",INDEX($U$2:$U$61,MATCH($A6,$X$2:$X$61,0))) -> 1 | J6: =IF($A6="","",INDEX($V$2:$V$61,MATCH($A6,$X$2:$X$61,0))) -> 3 | K6: =IF($A6="","",INDEX($AN$2:$AN$61,MATCH($A6,$X$2:$X$61,0))) -> V | N6: =IFERROR(INDEX(Partidos!$C$2:$C$1401,MATCH("TEAM|5",Partidos!$AE$2:$AE$1401,0)),IFERROR(INDEX(Partidos!$D$2:$D$1401,MATCH("TEAM|5",Partidos!$AF$2:$AF$1401,0)),"")) -> León | O6: =IF(N6="","",COUNTIF(Partidos!$C$2:$C$1401,N6)+COUNTIF(Partidos!$D$2:$D$1401,N6)) -> 1 | P6: =IF(N6="","",SUMPRODUCT((Partidos!$C$2:$C$1401=N6)*(Partidos!$E$2:$E$1401>Partidos!$F$2:$F$1401))+SUMPRODUCT((Partidos!$D$2:$D$1401=N6)*(Partidos!$F$2:$F$1401>Partidos!$E$2:$E$1401))) -> 0 | Q6: =IF(N6="","",SUMPRODUCT((((Partidos!$C$2:$C$1401=N6)+(Partidos!$D$2:$D$1401=N6)))*(Partidos!$E$2:$E$1401=Partidos!$F$2:$F$1401)*(Partidos!$C$2:$C$1401<>""))) -> 0 | R6: =IF(N6="","",O6-P6-Q6) -> 1 | S6: =IF(N6="","",SUMIF(Partidos!$C$2:$C$1401,N6,Partidos!$E$2:$E$1401)+SUMIF(Partidos!$D$2:$D$1401,N6,Partidos!$F$2:$F$1401)) -> 2 | T6: =IF(N6="","",SUMIF(Partidos!$C$2:$C$1401,N6,Partidos!$F$2:$F$1401)+SUMIF(Partidos!$D$2:$D$1401,N6,Partidos!$E$2:$E$1401)) -> 3 | U6: =IF(N6="","",S6-T6) -> -1 | V6: =IF(N6="","",P6*3+Q6) -> 0 | W6: =IF(N6="","",V6*1000000+U6*1000+S6+(ROW()*0.0000001)) -> -998 | X6: =IF(N6="","",RANK(W6,$W$2:$W$61)) -> 12 | Y6: =IF(N6="","",O6-4) -> -3 | Z6: =IF(N6="","",O6-3) -> -2 | AA6: =IF(N6="","",O6-2) -> -1 | AB6: =IF(N6="","",O6-1) -> 0 | AC6: =IF(N6="","",O6-0) -> 1 | AD6: =IF(OR(N6="",Y6=""),"",IF(Y6<1,"",IFERROR(MATCH($N6&"|"&Y6,Partidos!$Y:$Y,0),IFERROR(MATCH($N6&"|"&Y6,Partidos!$Z:$Z,0),"")))) | AE6: =IF(OR(N6="",Z6=""),"",IF(Z6<1,"",IFERROR(MATCH($N6&"|"&Z6,Partidos!$Y:$Y,0),IFERROR(MATCH($N6&"|"&Z6,Partidos!$Z:$Z,0),"")))) | AF6: =IF(OR(N6="",AA6=""),"",IF(AA6<1,"",IFERROR(MATCH($N6&"|"&AA6,Partidos!$Y:$Y,0),IFERROR(MATCH($N6&"|"&AA6,Partidos!$Z:$Z,0),"")))) | AG6: =IF(OR(N6="",AB6=""),"",IF(AB6<1,"",IFERROR(MATCH($N6&"|"&AB6,Partidos!$Y:$Y,0),IFERROR(MATCH($N6&"|"&AB6,Partidos!$Z:$Z,0),"")))) | AH6: =IF(OR(N6="",AC6=""),"",IF(AC6<1,"",IFERROR(MATCH($N6&"|"&AC6,Partidos!$Y:$Y,0),IFERROR(MATCH($N6&"|"&AC6,Partidos!$Z:$Z,0),"")))) -> 4 | AI6: =IF(AD6="","",IF(INDEX(Partidos!$C:$C,AD6)=$N6,IF(INDEX(Partidos!$E:$E,AD6)>INDEX(Partidos!$F:$F,AD6),"V",IF(INDEX(Partidos!$E:$E,AD6)=INDEX(Partidos!$F:$F,AD6),"E","P")),IF(INDEX(Partidos!$F:$F,AD6)>INDEX(Partidos!$E:$E,AD6),"V",IF(INDEX(Partidos!$F:$F,AD6)=INDEX(Partidos!$E:$E,AD6),"E","P")))) | AJ6: =IF(AE6="","",IF(INDEX(Partidos!$C:$C,AE6)=$N6,IF(INDEX(Partidos!$E:$E,AE6)>INDEX(Partidos!$F:$F,AE6),"V",IF(INDEX(Partidos!$E:$E,AE6)=INDEX(Partidos!$F:$F,AE6),"E","P")),IF(INDEX(Partidos!$F:$F,AE6)>INDEX(Partidos!$E:$E,AE6),"V",IF(INDEX(Partidos!$F:$F,AE6)=INDEX(Partidos!$E:$E,AE6),"E","P")))) | AK6: =IF(AF6="","",IF(INDEX(Partidos!$C:$C,AF6)=$N6,IF(INDEX(Partidos!$E:$E,AF6)>INDEX(Partidos!$F:$F,AF6),"V",IF(INDEX(Partidos!$E:$E,AF6)=INDEX(Partidos!$F:$F,AF6),"E","P")),IF(INDEX(Partidos!$F:$F,AF6)>INDEX(Partidos!$E:$E,AF6),"V",IF(INDEX(Partidos!$F:$F,AF6)=INDEX(Partidos!$E:$E,AF6),"E","P")))) | AL6: =IF(AG6="","",IF(INDEX(Partidos!$C:$C,AG6)=$N6,IF(INDEX(Partidos!$E:$E,AG6)>INDEX(Partidos!$F:$F,AG6),"V",IF(INDEX(Partidos!$E:$E,AG6)=INDEX(Partidos!$F:$F,AG6),"E","P")),IF(INDEX(Partidos!$F:$F,AG6)>INDEX(Partidos!$E:$E,AG6),"V",IF(INDEX(Partidos!$F:$F,AG6)=INDEX(Partidos!$E:$E,AG6),"E","P")))) | AM6: =IF(AH6="","",IF(INDEX(Partidos!$C:$C,AH6)=$N6,IF(INDEX(Partidos!$E:$E,AH6)>INDEX(Partidos!$F:$F,AH6),"V",IF(INDEX(Partidos!$E:$E,AH6)=INDEX(Partidos!$F:$F,AH6),"E","P")),IF(INDEX(Partidos!$F:$F,AH6)>INDEX(Partidos!$E:$E,AH6),"V",IF(INDEX(Partidos!$F:$F,AH6)=INDEX(Partidos!$E:$E,AH6),"E","P")))) -> P | AN6: =IF(N6="","",_xlfn.TEXTJOIN("-",TRUE(),AI6:AM6)) -> P | AO6: =IF(N6="","",RANK(S6,$S$2:$S$61,0)) -> 6 | AP6: =IF(AO6=1,SUMPRODUCT(($AO$2:AO6=1)*1),"") | AQ6: =IF(AO6=1,"GF|"&AP6,"") | AR6: =IF(N6="","",RANK(T6,$T$2:$T$61,1)) -> 14 | AS6: =IF(AR6=1,SUMPRODUCT(($AR$2:AR6=1)*1),"") | AT6: =IF(AR6=1,"GC|"&AS6,"")
A7: =IF(COUNT($X$2:$X$61)>=6,6,"") -> 6 | B7: =IF($A7="","",INDEX($N$2:$N$61,MATCH($A7,$X$2:$X$61,0))) -> Atlas | C7: =IF($A7="","",INDEX($O$2:$O$61,MATCH($A7,$X$2:$X$61,0))) -> 1 | D7: =IF($A7="","",INDEX($P$2:$P$61,MATCH($A7,$X$2:$X$61,0))) -> 1 | E7: =IF($A7="","",INDEX($Q$2:$Q$61,MATCH($A7,$X$2:$X$61,0))) -> 0 | F7: =IF($A7="","",INDEX($R$2:$R$61,MATCH($A7,$X$2:$X$61,0))) -> 0 | G7: =IF($A7="","",INDEX($S$2:$S$61,MATCH($A7,$X$2:$X$61,0))) -> 3 | H7: =IF($A7="","",INDEX($T$2:$T$61,MATCH($A7,$X$2:$X$61,0))) -> 2 | I7: =IF($A7="","",INDEX($U$2:$U$61,MATCH($A7,$X$2:$X$61,0))) -> 1 | J7: =IF($A7="","",INDEX($V$2:$V$61,MATCH($A7,$X$2:$X$61,0))) -> 3 | K7: =IF($A7="","",INDEX($AN$2:$AN$61,MATCH($A7,$X$2:$X$61,0))) -> V | N7: =IFERROR(INDEX(Partidos!$C$2:$C$1401,MATCH("TEAM|6",Partidos!$AE$2:$AE$1401,0)),IFERROR(INDEX(Partidos!$D$2:$D$1401,MATCH("TEAM|6",Partidos!$AF$2:$AF$1401,0)),"")) -> Atlas | O7: =IF(N7="","",COUNTIF(Partidos!$C$2:$C$1401,N7)+COUNTIF(Partidos!$D$2:$D$1401,N7)) -> 1 | P7: =IF(N7="","",SUMPRODUCT((Partidos!$C$2:$C$1401=N7)*(Partidos!$E$2:$E$1401>Partidos!$F$2:$F$1401))+SUMPRODUCT((Partidos!$D$2:$D$1401=N7)*(Partidos!$F$2:$F$1401>Partidos!$E$2:$E$1401))) -> 1 | Q7: =IF(N7="","",SUMPRODUCT((((Partidos!$C$2:$C$1401=N7)+(Partidos!$D$2:$D$1401=N7)))*(Partidos!$E$2:$E$1401=Partidos!$F$2:$F$1401)*(Partidos!$C$2:$C$1401<>""))) -> 0 | R7: =IF(N7="","",O7-P7-Q7) -> 0 | S7: =IF(N7="","",SUMIF(Partidos!$C$2:$C$1401,N7,Partidos!$E$2:$E$1401)+SUMIF(Partidos!$D$2:$D$1401,N7,Partidos!$F$2:$F$1401)) -> 3 | T7: =IF(N7="","",SUMIF(Partidos!$C$2:$C$1401,N7,Partidos!$F$2:$F$1401)+SUMIF(Partidos!$D$2:$D$1401,N7,Partidos!$E$2:$E$1401)) -> 2 | U7: =IF(N7="","",S7-T7) -> 1 | V7: =IF(N7="","",P7*3+Q7) -> 3 | W7: =IF(N7="","",V7*1000000+U7*1000+S7+(ROW()*0.0000001)) -> 3001003 | X7: =IF(N7="","",RANK(W7,$W$2:$W$61)) -> 6 | Y7: =IF(N7="","",O7-4) -> -3 | Z7: =IF(N7="","",O7-3) -> -2 | AA7: =IF(N7="","",O7-2) -> -1 | AB7: =IF(N7="","",O7-1) -> 0 | AC7: =IF(N7="","",O7-0) -> 1 | AD7: =IF(OR(N7="",Y7=""),"",IF(Y7<1,"",IFERROR(MATCH($N7&"|"&Y7,Partidos!$Y:$Y,0),IFERROR(MATCH($N7&"|"&Y7,Partidos!$Z:$Z,0),"")))) | AE7: =IF(OR(N7="",Z7=""),"",IF(Z7<1,"",IFERROR(MATCH($N7&"|"&Z7,Partidos!$Y:$Y,0),IFERROR(MATCH($N7&"|"&Z7,Partidos!$Z:$Z,0),"")))) | AF7: =IF(OR(N7="",AA7=""),"",IF(AA7<1,"",IFERROR(MATCH($N7&"|"&AA7,Partidos!$Y:$Y,0),IFERROR(MATCH($N7&"|"&AA7,Partidos!$Z:$Z,0),"")))) | AG7: =IF(OR(N7="",AB7=""),"",IF(AB7<1,"",IFERROR(MATCH($N7&"|"&AB7,Partidos!$Y:$Y,0),IFERROR(MATCH($N7&"|"&AB7,Partidos!$Z:$Z,0),"")))) | AH7: =IF(OR(N7="",AC7=""),"",IF(AC7<1,"",IFERROR(MATCH($N7&"|"&AC7,Partidos!$Y:$Y,0),IFERROR(MATCH($N7&"|"&AC7,Partidos!$Z:$Z,0),"")))) -> 4 | AI7: =IF(AD7="","",IF(INDEX(Partidos!$C:$C,AD7)=$N7,IF(INDEX(Partidos!$E:$E,AD7)>INDEX(Partidos!$F:$F,AD7),"V",IF(INDEX(Partidos!$E:$E,AD7)=INDEX(Partidos!$F:$F,AD7),"E","P")),IF(INDEX(Partidos!$F:$F,AD7)>INDEX(Partidos!$E:$E,AD7),"V",IF(INDEX(Partidos!$F:$F,AD7)=INDEX(Partidos!$E:$E,AD7),"E","P")))) | AJ7: =IF(AE7="","",IF(INDEX(Partidos!$C:$C,AE7)=$N7,IF(INDEX(Partidos!$E:$E,AE7)>INDEX(Partidos!$F:$F,AE7),"V",IF(INDEX(Partidos!$E:$E,AE7)=INDEX(Partidos!$F:$F,AE7),"E","P")),IF(INDEX(Partidos!$F:$F,AE7)>INDEX(Partidos!$E:$E,AE7),"V",IF(INDEX(Partidos!$F:$F,AE7)=INDEX(Partidos!$E:$E,AE7),"E","P")))) | AK7: =IF(AF7="","",IF(INDEX(Partidos!$C:$C,AF7)=$N7,IF(INDEX(Partidos!$E:$E,AF7)>INDEX(Partidos!$F:$F,AF7),"V",IF(INDEX(Partidos!$E:$E,AF7)=INDEX(Partidos!$F:$F,AF7),"E","P")),IF(INDEX(Partidos!$F:$F,AF7)>INDEX(Partidos!$E:$E,AF7),"V",IF(INDEX(Partidos!$F:$F,AF7)=INDEX(Partidos!$E:$E,AF7),"E","P")))) | AL7: =IF(AG7="","",IF(INDEX(Partidos!$C:$C,AG7)=$N7,IF(INDEX(Partidos!$E:$E,AG7)>INDEX(Partidos!$F:$F,AG7),"V",IF(INDEX(Partidos!$E:$E,AG7)=INDEX(Partidos!$F:$F,AG7),"E","P")),IF(INDEX(Partidos!$F:$F,AG7)>INDEX(Partidos!$E:$E,AG7),"V",IF(INDEX(Partidos!$F:$F,AG7)=INDEX(Partidos!$E:$E,AG7),"E","P")))) | AM7: =IF(AH7="","",IF(INDEX(Partidos!$C:$C,AH7)=$N7,IF(INDEX(Partidos!$E:$E,AH7)>INDEX(Partidos!$F:$F,AH7),"V",IF(INDEX(Partidos!$E:$E,AH7)=INDEX(Partidos!$F:$F,AH7),"E","P")),IF(INDEX(Partidos!$F:$F,AH7)>INDEX(Partidos!$E:$E,AH7),"V",IF(INDEX(Partidos!$F:$F,AH7)=INDEX(Partidos!$E:$E,AH7),"E","P")))) -> V | AN7: =IF(N7="","",_xlfn.TEXTJOIN("-",TRUE(),AI7:AM7)) -> V | AO7: =IF(N7="","",RANK(S7,$S$2:$S$61,0)) -> 1 | AP7: =IF(AO7=1,SUMPRODUCT(($AO$2:AO7=1)*1),"") -> 2 | AQ7: =IF(AO7=1,"GF|"&AP7,"") -> GF|2 | AR7: =IF(N7="","",RANK(T7,$T$2:$T$61,1)) -> 9 | AS7: =IF(AR7=1,SUMPRODUCT(($AR$2:AR7=1)*1),"") | AT7: =IF(AR7=1,"GC|"&AS7,"")
A8: =IF(COUNT($X$2:$X$61)>=7,7,"") -> 7 | B8: =IF($A8="","",INDEX($N$2:$N$61,MATCH($A8,$X$2:$X$61,0))) -> Necaxa | C8: =IF($A8="","",INDEX($O$2:$O$61,MATCH($A8,$X$2:$X$61,0))) -> 1 | D8: =IF($A8="","",INDEX($P$2:$P$61,MATCH($A8,$X$2:$X$61,0))) -> 1 | E8: =IF($A8="","",INDEX($Q$2:$Q$61,MATCH($A8,$X$2:$X$61,0))) -> 0 | F8: =IF($A8="","",INDEX($R$2:$R$61,MATCH($A8,$X$2:$X$61,0))) -> 0 | G8: =IF($A8="","",INDEX($S$2:$S$61,MATCH($A8,$X$2:$X$61,0))) -> 2 | H8: =IF($A8="","",INDEX($T$2:$T$61,MATCH($A8,$X$2:$X$61,0))) -> 1 | I8: =IF($A8="","",INDEX($U$2:$U$61,MATCH($A8,$X$2:$X$61,0))) -> 1 | J8: =IF($A8="","",INDEX($V$2:$V$61,MATCH($A8,$X$2:$X$61,0))) -> 3 | K8: =IF($A8="","",INDEX($AN$2:$AN$61,MATCH($A8,$X$2:$X$61,0))) -> V | N8: =IFERROR(INDEX(Partidos!$C$2:$C$1401,MATCH("TEAM|7",Partidos!$AE$2:$AE$1401,0)),IFERROR(INDEX(Partidos!$D$2:$D$1401,MATCH("TEAM|7",Partidos!$AF$2:$AF$1401,0)),"")) -> Atlético de San Luis | O8: =IF(N8="","",COUNTIF(Partidos!$C$2:$C$1401,N8)+COUNTIF(Partidos!$D$2:$D$1401,N8)) -> 1 | P8: =IF(N8="","",SUMPRODUCT((Partidos!$C$2:$C$1401=N8)*(Partidos!$E$2:$E$1401>Partidos!$F$2:$F$1401))+SUMPRODUCT((Partidos!$D$2:$D$1401=N8)*(Partidos!$F$2:$F$1401>Partidos!$E$2:$E$1401))) -> 0 | Q8: =IF(N8="","",SUMPRODUCT((((Partidos!$C$2:$C$1401=N8)+(Partidos!$D$2:$D$1401=N8)))*(Partidos!$E$2:$E$1401=Partidos!$F$2:$F$1401)*(Partidos!$C$2:$C$1401<>""))) -> 0 | R8: =IF(N8="","",O8-P8-Q8) -> 1 | S8: =IF(N8="","",SUMIF(Partidos!$C$2:$C$1401,N8,Partidos!$E$2:$E$1401)+SUMIF(Partidos!$D$2:$D$1401,N8,Partidos!$F$2:$F$1401)) -> 2 | T8: =IF(N8="","",SUMIF(Partidos!$C$2:$C$1401,N8,Partidos!$F$2:$F$1401)+SUMIF(Partidos!$D$2:$D$1401,N8,Partidos!$E$2:$E$1401)) -> 3 | U8: =IF(N8="","",S8-T8) -> -1 | V8: =IF(N8="","",P8*3+Q8) -> 0 | W8: =IF(N8="","",V8*1000000+U8*1000+S8+(ROW()*0.0000001)) -> -998 | X8: =IF(N8="","",RANK(W8,$W$2:$W$61)) -> 11 | Y8: =IF(N8="","",O8-4) -> -3 | Z8: =IF(N8="","",O8-3) -> -2 | AA8: =IF(N8="","",O8-2) -> -1 | AB8: =IF(N8="","",O8-1) -> 0 | AC8: =IF(N8="","",O8-0) -> 1 | AD8: =IF(OR(N8="",Y8=""),"",IF(Y8<1,"",IFERROR(MATCH($N8&"|"&Y8,Partidos!$Y:$Y,0),IFERROR(MATCH($N8&"|"&Y8,Partidos!$Z:$Z,0),"")))) | AE8: =IF(OR(N8="",Z8=""),"",IF(Z8<1,"",IFERROR(MATCH($N8&"|"&Z8,Partidos!$Y:$Y,0),IFERROR(MATCH($N8&"|"&Z8,Partidos!$Z:$Z,0),"")))) | AF8: =IF(OR(N8="",AA8=""),"",IF(AA8<1,"",IFERROR(MATCH($N8&"|"&AA8,Partidos!$Y:$Y,0),IFERROR(MATCH($N8&"|"&AA8,Partidos!$Z:$Z,0),"")))) | AG8: =IF(OR(N8="",AB8=""),"",IF(AB8<1,"",IFERROR(MATCH($N8&"|"&AB8,Partidos!$Y:$Y,0),IFERROR(MATCH($N8&"|"&AB8,Partidos!$Z:$Z,0),"")))) | AH8: =IF(OR(N8="",AC8=""),"",IF(AC8<1,"",IFERROR(MATCH($N8&"|"&AC8,Partidos!$Y:$Y,0),IFERROR(MATCH($N8&"|"&AC8,Partidos!$Z:$Z,0),"")))) -> 5 | AI8: =IF(AD8="","",IF(INDEX(Partidos!$C:$C,AD8)=$N8,IF(INDEX(Partidos!$E:$E,AD8)>INDEX(Partidos!$F:$F,AD8),"V",IF(INDEX(Partidos!$E:$E,AD8)=INDEX(Partidos!$F:$F,AD8),"E","P")),IF(INDEX(Partidos!$F:$F,AD8)>INDEX(Partidos!$E:$E,AD8),"V",IF(INDEX(Partidos!$F:$F,AD8)=INDEX(Partidos!$E:$E,AD8),"E","P")))) | AJ8: =IF(AE8="","",IF(INDEX(Partidos!$C:$C,AE8)=$N8,IF(INDEX(Partidos!$E:$E,AE8)>INDEX(Partidos!$F:$F,AE8),"V",IF(INDEX(Partidos!$E:$E,AE8)=INDEX(Partidos!$F:$F,AE8),"E","P")),IF(INDEX(Partidos!$F:$F,AE8)>INDEX(Partidos!$E:$E,AE8),"V",IF(INDEX(Partidos!$F:$F,AE8)=INDEX(Partidos!$E:$E,AE8),"E","P")))) | AK8: =IF(AF8="","",IF(INDEX(Partidos!$C:$C,AF8)=$N8,IF(INDEX(Partidos!$E:$E,AF8)>INDEX(Partidos!$F:$F,AF8),"V",IF(INDEX(Partidos!$E:$E,AF8)=INDEX(Partidos!$F:$F,AF8),"E","P")),IF(INDEX(Partidos!$F:$F,AF8)>INDEX(Partidos!$E:$E,AF8),"V",IF(INDEX(Partidos!$F:$F,AF8)=INDEX(Partidos!$E:$E,AF8),"E","P")))) | AL8: =IF(AG8="","",IF(INDEX(Partidos!$C:$C,AG8)=$N8,IF(INDEX(Partidos!$E:$E,AG8)>INDEX(Partidos!$F:$F,AG8),"V",IF(INDEX(Partidos!$E:$E,AG8)=INDEX(Partidos!$F:$F,AG8),"E","P")),IF(INDEX(Partidos!$F:$F,AG8)>INDEX(Partidos!$E:$E,AG8),"V",IF(INDEX(Partidos!$F:$F,AG8)=INDEX(Partidos!$E:$E,AG8),"E","P")))) | AM8: =IF(AH8="","",IF(INDEX(Partidos!$C:$C,AH8)=$N8,IF(INDEX(Partidos!$E:$E,AH8)>INDEX(Partidos!$F:$F,AH8),"V",IF(INDEX(Partidos!$E:$E,AH8)=INDEX(Partidos!$F:$F,AH8),"E","P")),IF(INDEX(Partidos!$F:$F,AH8)>INDEX(Partidos!$E:$E,AH8),"V",IF(INDEX(Partidos!$F:$F,AH8)=INDEX(Partidos!$E:$E,AH8),"E","P")))) -> P | AN8: =IF(N8="","",_xlfn.TEXTJOIN("-",TRUE(),AI8:AM8)) -> P | AO8: =IF(N8="","",RANK(S8,$S$2:$S$61,0)) -> 6 | AP8: =IF(AO8=1,SUMPRODUCT(($AO$2:AO8=1)*1),"") | AQ8: =IF(AO8=1,"GF|"&AP8,"") | AR8: =IF(N8="","",RANK(T8,$T$2:$T$61,1)) -> 14 | AS8: =IF(AR8=1,SUMPRODUCT(($AR$2:AR8=1)*1),"") | AT8: =IF(AR8=1,"GC|"&AS8,"")
